[2025-04-20T20:56:00.243+0800] {processor.py:186} INFO - Started process (PID=87943) to work on /mnt/c/Users/wu_li/OneDrive/Desktop/Airflow_pract/dags/first_dag.py
[2025-04-20T20:56:00.245+0800] {processor.py:914} INFO - Processing file /mnt/c/Users/wu_li/OneDrive/Desktop/Airflow_pract/dags/first_dag.py for tasks to queue
[2025-04-20T20:56:00.250+0800] {logging_mixin.py:190} INFO - [2025-04-20T20:56:00.246+0800] {dagbag.py:588} INFO - Filling up the DagBag from /mnt/c/Users/wu_li/OneDrive/Desktop/Airflow_pract/dags/first_dag.py
[2025-04-20T20:56:00.293+0800] {logging_mixin.py:190} INFO - [2025-04-20T20:56:00.282+0800] {dagbag.py:387} ERROR - Failed to import: /mnt/c/Users/wu_li/OneDrive/Desktop/Airflow_pract/dags/first_dag.py
Traceback (most recent call last):
  File "/mnt/c/Users/wu_li/OneDrive/Desktop/Airflow_pract/venv/lib/python3.9/site-packages/airflow/models/dagbag.py", line 383, in parse
    loader.exec_module(new_module)
  File "<frozen importlib._bootstrap_external>", line 850, in exec_module
  File "<frozen importlib._bootstrap>", line 228, in _call_with_frames_removed
  File "/mnt/c/Users/wu_li/OneDrive/Desktop/Airflow_pract/dags/first_dag.py", line 2, in <module>
    from airflow import first_dag
ImportError: cannot import name 'first_dag' from 'airflow' (/mnt/c/Users/wu_li/OneDrive/Desktop/Airflow_pract/venv/lib/python3.9/site-packages/airflow/__init__.py)
[2025-04-20T20:56:00.296+0800] {processor.py:927} WARNING - No viable dags retrieved from /mnt/c/Users/wu_li/OneDrive/Desktop/Airflow_pract/dags/first_dag.py
[2025-04-20T20:56:00.345+0800] {processor.py:208} INFO - Processing /mnt/c/Users/wu_li/OneDrive/Desktop/Airflow_pract/dags/first_dag.py took 0.118 seconds
[2025-04-20T20:56:57.766+0800] {processor.py:186} INFO - Started process (PID=88596) to work on /mnt/c/Users/wu_li/OneDrive/Desktop/Airflow_pract/dags/first_dag.py
[2025-04-20T20:56:57.768+0800] {processor.py:914} INFO - Processing file /mnt/c/Users/wu_li/OneDrive/Desktop/Airflow_pract/dags/first_dag.py for tasks to queue
[2025-04-20T20:56:57.771+0800] {logging_mixin.py:190} INFO - [2025-04-20T20:56:57.770+0800] {dagbag.py:588} INFO - Filling up the DagBag from /mnt/c/Users/wu_li/OneDrive/Desktop/Airflow_pract/dags/first_dag.py
[2025-04-20T20:56:57.795+0800] {logging_mixin.py:190} INFO - [2025-04-20T20:56:57.787+0800] {dagbag.py:387} ERROR - Failed to import: /mnt/c/Users/wu_li/OneDrive/Desktop/Airflow_pract/dags/first_dag.py
Traceback (most recent call last):
  File "/mnt/c/Users/wu_li/OneDrive/Desktop/Airflow_pract/venv/lib/python3.9/site-packages/airflow/models/dagbag.py", line 383, in parse
    loader.exec_module(new_module)
  File "<frozen importlib._bootstrap_external>", line 850, in exec_module
  File "<frozen importlib._bootstrap>", line 228, in _call_with_frames_removed
  File "/mnt/c/Users/wu_li/OneDrive/Desktop/Airflow_pract/dags/first_dag.py", line 2, in <module>
    from airflow import first_dag
ImportError: cannot import name 'first_dag' from 'airflow' (/mnt/c/Users/wu_li/OneDrive/Desktop/Airflow_pract/venv/lib/python3.9/site-packages/airflow/__init__.py)
[2025-04-20T20:56:57.797+0800] {processor.py:927} WARNING - No viable dags retrieved from /mnt/c/Users/wu_li/OneDrive/Desktop/Airflow_pract/dags/first_dag.py
[2025-04-20T20:56:57.837+0800] {processor.py:208} INFO - Processing /mnt/c/Users/wu_li/OneDrive/Desktop/Airflow_pract/dags/first_dag.py took 0.083 seconds
[2025-04-20T20:57:42.783+0800] {processor.py:186} INFO - Started process (PID=89138) to work on /mnt/c/Users/wu_li/OneDrive/Desktop/Airflow_pract/dags/first_dag.py
[2025-04-20T20:57:42.784+0800] {processor.py:914} INFO - Processing file /mnt/c/Users/wu_li/OneDrive/Desktop/Airflow_pract/dags/first_dag.py for tasks to queue
[2025-04-20T20:57:42.787+0800] {logging_mixin.py:190} INFO - [2025-04-20T20:57:42.786+0800] {dagbag.py:588} INFO - Filling up the DagBag from /mnt/c/Users/wu_li/OneDrive/Desktop/Airflow_pract/dags/first_dag.py
[2025-04-20T20:57:42.810+0800] {logging_mixin.py:190} INFO - [2025-04-20T20:57:42.802+0800] {dagbag.py:387} ERROR - Failed to import: /mnt/c/Users/wu_li/OneDrive/Desktop/Airflow_pract/dags/first_dag.py
Traceback (most recent call last):
  File "/mnt/c/Users/wu_li/OneDrive/Desktop/Airflow_pract/venv/lib/python3.9/site-packages/airflow/models/dagbag.py", line 383, in parse
    loader.exec_module(new_module)
  File "<frozen importlib._bootstrap_external>", line 850, in exec_module
  File "<frozen importlib._bootstrap>", line 228, in _call_with_frames_removed
  File "/mnt/c/Users/wu_li/OneDrive/Desktop/Airflow_pract/dags/first_dag.py", line 2, in <module>
    from airflow import first_dag
ImportError: cannot import name 'first_dag' from 'airflow' (/mnt/c/Users/wu_li/OneDrive/Desktop/Airflow_pract/venv/lib/python3.9/site-packages/airflow/__init__.py)
[2025-04-20T20:57:42.812+0800] {processor.py:927} WARNING - No viable dags retrieved from /mnt/c/Users/wu_li/OneDrive/Desktop/Airflow_pract/dags/first_dag.py
[2025-04-20T20:57:42.849+0800] {processor.py:208} INFO - Processing /mnt/c/Users/wu_li/OneDrive/Desktop/Airflow_pract/dags/first_dag.py took 0.077 seconds
[2025-04-20T20:58:26.988+0800] {processor.py:186} INFO - Started process (PID=89677) to work on /mnt/c/Users/wu_li/OneDrive/Desktop/Airflow_pract/dags/first_dag.py
[2025-04-20T20:58:26.991+0800] {processor.py:914} INFO - Processing file /mnt/c/Users/wu_li/OneDrive/Desktop/Airflow_pract/dags/first_dag.py for tasks to queue
[2025-04-20T20:58:26.997+0800] {logging_mixin.py:190} INFO - [2025-04-20T20:58:26.995+0800] {dagbag.py:588} INFO - Filling up the DagBag from /mnt/c/Users/wu_li/OneDrive/Desktop/Airflow_pract/dags/first_dag.py
[2025-04-20T20:58:27.053+0800] {logging_mixin.py:190} INFO - [2025-04-20T20:58:27.036+0800] {dagbag.py:387} ERROR - Failed to import: /mnt/c/Users/wu_li/OneDrive/Desktop/Airflow_pract/dags/first_dag.py
Traceback (most recent call last):
  File "/mnt/c/Users/wu_li/OneDrive/Desktop/Airflow_pract/venv/lib/python3.9/site-packages/airflow/models/dagbag.py", line 383, in parse
    loader.exec_module(new_module)
  File "<frozen importlib._bootstrap_external>", line 850, in exec_module
  File "<frozen importlib._bootstrap>", line 228, in _call_with_frames_removed
  File "/mnt/c/Users/wu_li/OneDrive/Desktop/Airflow_pract/dags/first_dag.py", line 2, in <module>
    from airflow import first_dag
ImportError: cannot import name 'first_dag' from 'airflow' (/mnt/c/Users/wu_li/OneDrive/Desktop/Airflow_pract/venv/lib/python3.9/site-packages/airflow/__init__.py)
[2025-04-20T20:58:27.056+0800] {processor.py:927} WARNING - No viable dags retrieved from /mnt/c/Users/wu_li/OneDrive/Desktop/Airflow_pract/dags/first_dag.py
[2025-04-20T20:58:27.150+0800] {processor.py:208} INFO - Processing /mnt/c/Users/wu_li/OneDrive/Desktop/Airflow_pract/dags/first_dag.py took 0.190 seconds
[2025-04-20T20:59:12.821+0800] {processor.py:186} INFO - Started process (PID=90216) to work on /mnt/c/Users/wu_li/OneDrive/Desktop/Airflow_pract/dags/first_dag.py
[2025-04-20T20:59:12.824+0800] {processor.py:914} INFO - Processing file /mnt/c/Users/wu_li/OneDrive/Desktop/Airflow_pract/dags/first_dag.py for tasks to queue
[2025-04-20T20:59:12.834+0800] {logging_mixin.py:190} INFO - [2025-04-20T20:59:12.833+0800] {dagbag.py:588} INFO - Filling up the DagBag from /mnt/c/Users/wu_li/OneDrive/Desktop/Airflow_pract/dags/first_dag.py
[2025-04-20T20:59:12.892+0800] {logging_mixin.py:190} INFO - [2025-04-20T20:59:12.872+0800] {dagbag.py:387} ERROR - Failed to import: /mnt/c/Users/wu_li/OneDrive/Desktop/Airflow_pract/dags/first_dag.py
Traceback (most recent call last):
  File "/mnt/c/Users/wu_li/OneDrive/Desktop/Airflow_pract/venv/lib/python3.9/site-packages/airflow/models/dagbag.py", line 383, in parse
    loader.exec_module(new_module)
  File "<frozen importlib._bootstrap_external>", line 850, in exec_module
  File "<frozen importlib._bootstrap>", line 228, in _call_with_frames_removed
  File "/mnt/c/Users/wu_li/OneDrive/Desktop/Airflow_pract/dags/first_dag.py", line 2, in <module>
    from airflow import first_dag
ImportError: cannot import name 'first_dag' from 'airflow' (/mnt/c/Users/wu_li/OneDrive/Desktop/Airflow_pract/venv/lib/python3.9/site-packages/airflow/__init__.py)
[2025-04-20T20:59:12.895+0800] {processor.py:927} WARNING - No viable dags retrieved from /mnt/c/Users/wu_li/OneDrive/Desktop/Airflow_pract/dags/first_dag.py
[2025-04-20T20:59:12.969+0800] {processor.py:208} INFO - Processing /mnt/c/Users/wu_li/OneDrive/Desktop/Airflow_pract/dags/first_dag.py took 0.171 seconds
[2025-04-20T20:59:54.812+0800] {processor.py:186} INFO - Started process (PID=90683) to work on /mnt/c/Users/wu_li/OneDrive/Desktop/Airflow_pract/dags/first_dag.py
[2025-04-20T20:59:54.814+0800] {processor.py:914} INFO - Processing file /mnt/c/Users/wu_li/OneDrive/Desktop/Airflow_pract/dags/first_dag.py for tasks to queue
[2025-04-20T20:59:54.816+0800] {logging_mixin.py:190} INFO - [2025-04-20T20:59:54.815+0800] {dagbag.py:588} INFO - Filling up the DagBag from /mnt/c/Users/wu_li/OneDrive/Desktop/Airflow_pract/dags/first_dag.py
[2025-04-20T20:59:54.841+0800] {logging_mixin.py:190} INFO - [2025-04-20T20:59:54.831+0800] {dagbag.py:387} ERROR - Failed to import: /mnt/c/Users/wu_li/OneDrive/Desktop/Airflow_pract/dags/first_dag.py
Traceback (most recent call last):
  File "/mnt/c/Users/wu_li/OneDrive/Desktop/Airflow_pract/venv/lib/python3.9/site-packages/airflow/models/dagbag.py", line 383, in parse
    loader.exec_module(new_module)
  File "<frozen importlib._bootstrap_external>", line 850, in exec_module
  File "<frozen importlib._bootstrap>", line 228, in _call_with_frames_removed
  File "/mnt/c/Users/wu_li/OneDrive/Desktop/Airflow_pract/dags/first_dag.py", line 2, in <module>
    from airflow import first_dag
ImportError: cannot import name 'first_dag' from 'airflow' (/mnt/c/Users/wu_li/OneDrive/Desktop/Airflow_pract/venv/lib/python3.9/site-packages/airflow/__init__.py)
[2025-04-20T20:59:54.843+0800] {processor.py:927} WARNING - No viable dags retrieved from /mnt/c/Users/wu_li/OneDrive/Desktop/Airflow_pract/dags/first_dag.py
[2025-04-20T20:59:54.881+0800] {processor.py:208} INFO - Processing /mnt/c/Users/wu_li/OneDrive/Desktop/Airflow_pract/dags/first_dag.py took 0.080 seconds
[2025-04-20T21:00:38.885+0800] {processor.py:186} INFO - Started process (PID=91220) to work on /mnt/c/Users/wu_li/OneDrive/Desktop/Airflow_pract/dags/first_dag.py
[2025-04-20T21:00:38.887+0800] {processor.py:914} INFO - Processing file /mnt/c/Users/wu_li/OneDrive/Desktop/Airflow_pract/dags/first_dag.py for tasks to queue
[2025-04-20T21:00:38.891+0800] {logging_mixin.py:190} INFO - [2025-04-20T21:00:38.889+0800] {dagbag.py:588} INFO - Filling up the DagBag from /mnt/c/Users/wu_li/OneDrive/Desktop/Airflow_pract/dags/first_dag.py
[2025-04-20T21:00:38.930+0800] {logging_mixin.py:190} INFO - [2025-04-20T21:00:38.913+0800] {dagbag.py:387} ERROR - Failed to import: /mnt/c/Users/wu_li/OneDrive/Desktop/Airflow_pract/dags/first_dag.py
Traceback (most recent call last):
  File "/mnt/c/Users/wu_li/OneDrive/Desktop/Airflow_pract/venv/lib/python3.9/site-packages/airflow/models/dagbag.py", line 383, in parse
    loader.exec_module(new_module)
  File "<frozen importlib._bootstrap_external>", line 850, in exec_module
  File "<frozen importlib._bootstrap>", line 228, in _call_with_frames_removed
  File "/mnt/c/Users/wu_li/OneDrive/Desktop/Airflow_pract/dags/first_dag.py", line 2, in <module>
    from airflow import first_dag
ImportError: cannot import name 'first_dag' from 'airflow' (/mnt/c/Users/wu_li/OneDrive/Desktop/Airflow_pract/venv/lib/python3.9/site-packages/airflow/__init__.py)
[2025-04-20T21:00:38.934+0800] {processor.py:927} WARNING - No viable dags retrieved from /mnt/c/Users/wu_li/OneDrive/Desktop/Airflow_pract/dags/first_dag.py
[2025-04-20T21:00:39.002+0800] {processor.py:208} INFO - Processing /mnt/c/Users/wu_li/OneDrive/Desktop/Airflow_pract/dags/first_dag.py took 0.139 seconds
[2025-04-20T21:01:26.407+0800] {processor.py:186} INFO - Started process (PID=91692) to work on /mnt/c/Users/wu_li/OneDrive/Desktop/Airflow_pract/dags/first_dag.py
[2025-04-20T21:01:26.408+0800] {processor.py:914} INFO - Processing file /mnt/c/Users/wu_li/OneDrive/Desktop/Airflow_pract/dags/first_dag.py for tasks to queue
[2025-04-20T21:01:26.411+0800] {logging_mixin.py:190} INFO - [2025-04-20T21:01:26.410+0800] {dagbag.py:588} INFO - Filling up the DagBag from /mnt/c/Users/wu_li/OneDrive/Desktop/Airflow_pract/dags/first_dag.py
[2025-04-20T21:01:26.438+0800] {logging_mixin.py:190} INFO - [2025-04-20T21:01:26.427+0800] {dagbag.py:387} ERROR - Failed to import: /mnt/c/Users/wu_li/OneDrive/Desktop/Airflow_pract/dags/first_dag.py
Traceback (most recent call last):
  File "/mnt/c/Users/wu_li/OneDrive/Desktop/Airflow_pract/venv/lib/python3.9/site-packages/airflow/models/dagbag.py", line 383, in parse
    loader.exec_module(new_module)
  File "<frozen importlib._bootstrap_external>", line 850, in exec_module
  File "<frozen importlib._bootstrap>", line 228, in _call_with_frames_removed
  File "/mnt/c/Users/wu_li/OneDrive/Desktop/Airflow_pract/dags/first_dag.py", line 2, in <module>
    from airflow import first_dag
ImportError: cannot import name 'first_dag' from 'airflow' (/mnt/c/Users/wu_li/OneDrive/Desktop/Airflow_pract/venv/lib/python3.9/site-packages/airflow/__init__.py)
[2025-04-20T21:01:26.442+0800] {processor.py:927} WARNING - No viable dags retrieved from /mnt/c/Users/wu_li/OneDrive/Desktop/Airflow_pract/dags/first_dag.py
[2025-04-20T21:01:26.487+0800] {processor.py:208} INFO - Processing /mnt/c/Users/wu_li/OneDrive/Desktop/Airflow_pract/dags/first_dag.py took 0.094 seconds
[2025-04-20T21:02:11.559+0800] {processor.py:186} INFO - Started process (PID=92201) to work on /mnt/c/Users/wu_li/OneDrive/Desktop/Airflow_pract/dags/first_dag.py
[2025-04-20T21:02:11.560+0800] {processor.py:914} INFO - Processing file /mnt/c/Users/wu_li/OneDrive/Desktop/Airflow_pract/dags/first_dag.py for tasks to queue
[2025-04-20T21:02:11.563+0800] {logging_mixin.py:190} INFO - [2025-04-20T21:02:11.562+0800] {dagbag.py:588} INFO - Filling up the DagBag from /mnt/c/Users/wu_li/OneDrive/Desktop/Airflow_pract/dags/first_dag.py
[2025-04-20T21:02:11.588+0800] {logging_mixin.py:190} INFO - [2025-04-20T21:02:11.579+0800] {dagbag.py:387} ERROR - Failed to import: /mnt/c/Users/wu_li/OneDrive/Desktop/Airflow_pract/dags/first_dag.py
Traceback (most recent call last):
  File "/mnt/c/Users/wu_li/OneDrive/Desktop/Airflow_pract/venv/lib/python3.9/site-packages/airflow/models/dagbag.py", line 383, in parse
    loader.exec_module(new_module)
  File "<frozen importlib._bootstrap_external>", line 850, in exec_module
  File "<frozen importlib._bootstrap>", line 228, in _call_with_frames_removed
  File "/mnt/c/Users/wu_li/OneDrive/Desktop/Airflow_pract/dags/first_dag.py", line 2, in <module>
    from airflow import first_dag
ImportError: cannot import name 'first_dag' from 'airflow' (/mnt/c/Users/wu_li/OneDrive/Desktop/Airflow_pract/venv/lib/python3.9/site-packages/airflow/__init__.py)
[2025-04-20T21:02:11.591+0800] {processor.py:927} WARNING - No viable dags retrieved from /mnt/c/Users/wu_li/OneDrive/Desktop/Airflow_pract/dags/first_dag.py
[2025-04-20T21:02:11.627+0800] {processor.py:208} INFO - Processing /mnt/c/Users/wu_li/OneDrive/Desktop/Airflow_pract/dags/first_dag.py took 0.080 seconds
[2025-04-20T21:02:53.907+0800] {processor.py:186} INFO - Started process (PID=92699) to work on /mnt/c/Users/wu_li/OneDrive/Desktop/Airflow_pract/dags/first_dag.py
[2025-04-20T21:02:53.909+0800] {processor.py:914} INFO - Processing file /mnt/c/Users/wu_li/OneDrive/Desktop/Airflow_pract/dags/first_dag.py for tasks to queue
[2025-04-20T21:02:53.911+0800] {logging_mixin.py:190} INFO - [2025-04-20T21:02:53.910+0800] {dagbag.py:588} INFO - Filling up the DagBag from /mnt/c/Users/wu_li/OneDrive/Desktop/Airflow_pract/dags/first_dag.py
[2025-04-20T21:02:53.940+0800] {logging_mixin.py:190} INFO - [2025-04-20T21:02:53.930+0800] {dagbag.py:387} ERROR - Failed to import: /mnt/c/Users/wu_li/OneDrive/Desktop/Airflow_pract/dags/first_dag.py
Traceback (most recent call last):
  File "/mnt/c/Users/wu_li/OneDrive/Desktop/Airflow_pract/venv/lib/python3.9/site-packages/airflow/models/dagbag.py", line 383, in parse
    loader.exec_module(new_module)
  File "<frozen importlib._bootstrap_external>", line 850, in exec_module
  File "<frozen importlib._bootstrap>", line 228, in _call_with_frames_removed
  File "/mnt/c/Users/wu_li/OneDrive/Desktop/Airflow_pract/dags/first_dag.py", line 2, in <module>
    from airflow import first_dag
ImportError: cannot import name 'first_dag' from 'airflow' (/mnt/c/Users/wu_li/OneDrive/Desktop/Airflow_pract/venv/lib/python3.9/site-packages/airflow/__init__.py)
[2025-04-20T21:02:53.943+0800] {processor.py:927} WARNING - No viable dags retrieved from /mnt/c/Users/wu_li/OneDrive/Desktop/Airflow_pract/dags/first_dag.py
[2025-04-20T21:02:53.982+0800] {processor.py:208} INFO - Processing /mnt/c/Users/wu_li/OneDrive/Desktop/Airflow_pract/dags/first_dag.py took 0.088 seconds
[2025-04-20T21:03:38.325+0800] {processor.py:186} INFO - Started process (PID=93238) to work on /mnt/c/Users/wu_li/OneDrive/Desktop/Airflow_pract/dags/first_dag.py
[2025-04-20T21:03:38.327+0800] {processor.py:914} INFO - Processing file /mnt/c/Users/wu_li/OneDrive/Desktop/Airflow_pract/dags/first_dag.py for tasks to queue
[2025-04-20T21:03:38.329+0800] {logging_mixin.py:190} INFO - [2025-04-20T21:03:38.328+0800] {dagbag.py:588} INFO - Filling up the DagBag from /mnt/c/Users/wu_li/OneDrive/Desktop/Airflow_pract/dags/first_dag.py
[2025-04-20T21:03:38.353+0800] {logging_mixin.py:190} INFO - [2025-04-20T21:03:38.344+0800] {dagbag.py:387} ERROR - Failed to import: /mnt/c/Users/wu_li/OneDrive/Desktop/Airflow_pract/dags/first_dag.py
Traceback (most recent call last):
  File "/mnt/c/Users/wu_li/OneDrive/Desktop/Airflow_pract/venv/lib/python3.9/site-packages/airflow/models/dagbag.py", line 383, in parse
    loader.exec_module(new_module)
  File "<frozen importlib._bootstrap_external>", line 850, in exec_module
  File "<frozen importlib._bootstrap>", line 228, in _call_with_frames_removed
  File "/mnt/c/Users/wu_li/OneDrive/Desktop/Airflow_pract/dags/first_dag.py", line 2, in <module>
    from airflow import first_dag
ImportError: cannot import name 'first_dag' from 'airflow' (/mnt/c/Users/wu_li/OneDrive/Desktop/Airflow_pract/venv/lib/python3.9/site-packages/airflow/__init__.py)
[2025-04-20T21:03:38.355+0800] {processor.py:927} WARNING - No viable dags retrieved from /mnt/c/Users/wu_li/OneDrive/Desktop/Airflow_pract/dags/first_dag.py
[2025-04-20T21:03:38.395+0800] {processor.py:208} INFO - Processing /mnt/c/Users/wu_li/OneDrive/Desktop/Airflow_pract/dags/first_dag.py took 0.083 seconds
[2025-04-20T21:04:21.333+0800] {processor.py:186} INFO - Started process (PID=93777) to work on /mnt/c/Users/wu_li/OneDrive/Desktop/Airflow_pract/dags/first_dag.py
[2025-04-20T21:04:21.336+0800] {processor.py:914} INFO - Processing file /mnt/c/Users/wu_li/OneDrive/Desktop/Airflow_pract/dags/first_dag.py for tasks to queue
[2025-04-20T21:04:21.340+0800] {logging_mixin.py:190} INFO - [2025-04-20T21:04:21.339+0800] {dagbag.py:588} INFO - Filling up the DagBag from /mnt/c/Users/wu_li/OneDrive/Desktop/Airflow_pract/dags/first_dag.py
[2025-04-20T21:04:21.377+0800] {logging_mixin.py:190} INFO - [2025-04-20T21:04:21.364+0800] {dagbag.py:387} ERROR - Failed to import: /mnt/c/Users/wu_li/OneDrive/Desktop/Airflow_pract/dags/first_dag.py
Traceback (most recent call last):
  File "/mnt/c/Users/wu_li/OneDrive/Desktop/Airflow_pract/venv/lib/python3.9/site-packages/airflow/models/dagbag.py", line 383, in parse
    loader.exec_module(new_module)
  File "<frozen importlib._bootstrap_external>", line 850, in exec_module
  File "<frozen importlib._bootstrap>", line 228, in _call_with_frames_removed
  File "/mnt/c/Users/wu_li/OneDrive/Desktop/Airflow_pract/dags/first_dag.py", line 2, in <module>
    from airflow import first_dag
ImportError: cannot import name 'first_dag' from 'airflow' (/mnt/c/Users/wu_li/OneDrive/Desktop/Airflow_pract/venv/lib/python3.9/site-packages/airflow/__init__.py)
[2025-04-20T21:04:21.381+0800] {processor.py:927} WARNING - No viable dags retrieved from /mnt/c/Users/wu_li/OneDrive/Desktop/Airflow_pract/dags/first_dag.py
[2025-04-20T21:04:21.447+0800] {processor.py:208} INFO - Processing /mnt/c/Users/wu_li/OneDrive/Desktop/Airflow_pract/dags/first_dag.py took 0.131 seconds
[2025-04-20T21:05:06.352+0800] {processor.py:186} INFO - Started process (PID=94317) to work on /mnt/c/Users/wu_li/OneDrive/Desktop/Airflow_pract/dags/first_dag.py
[2025-04-20T21:05:06.354+0800] {processor.py:914} INFO - Processing file /mnt/c/Users/wu_li/OneDrive/Desktop/Airflow_pract/dags/first_dag.py for tasks to queue
[2025-04-20T21:05:06.359+0800] {logging_mixin.py:190} INFO - [2025-04-20T21:05:06.357+0800] {dagbag.py:588} INFO - Filling up the DagBag from /mnt/c/Users/wu_li/OneDrive/Desktop/Airflow_pract/dags/first_dag.py
[2025-04-20T21:05:06.392+0800] {logging_mixin.py:190} INFO - [2025-04-20T21:05:06.380+0800] {dagbag.py:387} ERROR - Failed to import: /mnt/c/Users/wu_li/OneDrive/Desktop/Airflow_pract/dags/first_dag.py
Traceback (most recent call last):
  File "/mnt/c/Users/wu_li/OneDrive/Desktop/Airflow_pract/venv/lib/python3.9/site-packages/airflow/models/dagbag.py", line 383, in parse
    loader.exec_module(new_module)
  File "<frozen importlib._bootstrap_external>", line 850, in exec_module
  File "<frozen importlib._bootstrap>", line 228, in _call_with_frames_removed
  File "/mnt/c/Users/wu_li/OneDrive/Desktop/Airflow_pract/dags/first_dag.py", line 2, in <module>
    from airflow import first_dag
ImportError: cannot import name 'first_dag' from 'airflow' (/mnt/c/Users/wu_li/OneDrive/Desktop/Airflow_pract/venv/lib/python3.9/site-packages/airflow/__init__.py)
[2025-04-20T21:05:06.395+0800] {processor.py:927} WARNING - No viable dags retrieved from /mnt/c/Users/wu_li/OneDrive/Desktop/Airflow_pract/dags/first_dag.py
[2025-04-20T21:05:06.458+0800] {processor.py:208} INFO - Processing /mnt/c/Users/wu_li/OneDrive/Desktop/Airflow_pract/dags/first_dag.py took 0.123 seconds
[2025-04-20T21:05:52.101+0800] {processor.py:186} INFO - Started process (PID=94858) to work on /mnt/c/Users/wu_li/OneDrive/Desktop/Airflow_pract/dags/first_dag.py
[2025-04-20T21:05:52.103+0800] {processor.py:914} INFO - Processing file /mnt/c/Users/wu_li/OneDrive/Desktop/Airflow_pract/dags/first_dag.py for tasks to queue
[2025-04-20T21:05:52.108+0800] {logging_mixin.py:190} INFO - [2025-04-20T21:05:52.106+0800] {dagbag.py:588} INFO - Filling up the DagBag from /mnt/c/Users/wu_li/OneDrive/Desktop/Airflow_pract/dags/first_dag.py
[2025-04-20T21:05:52.144+0800] {logging_mixin.py:190} INFO - [2025-04-20T21:05:52.131+0800] {dagbag.py:387} ERROR - Failed to import: /mnt/c/Users/wu_li/OneDrive/Desktop/Airflow_pract/dags/first_dag.py
Traceback (most recent call last):
  File "/mnt/c/Users/wu_li/OneDrive/Desktop/Airflow_pract/venv/lib/python3.9/site-packages/airflow/models/dagbag.py", line 383, in parse
    loader.exec_module(new_module)
  File "<frozen importlib._bootstrap_external>", line 850, in exec_module
  File "<frozen importlib._bootstrap>", line 228, in _call_with_frames_removed
  File "/mnt/c/Users/wu_li/OneDrive/Desktop/Airflow_pract/dags/first_dag.py", line 2, in <module>
    from airflow import first_dag
ImportError: cannot import name 'first_dag' from 'airflow' (/mnt/c/Users/wu_li/OneDrive/Desktop/Airflow_pract/venv/lib/python3.9/site-packages/airflow/__init__.py)
[2025-04-20T21:05:52.147+0800] {processor.py:927} WARNING - No viable dags retrieved from /mnt/c/Users/wu_li/OneDrive/Desktop/Airflow_pract/dags/first_dag.py
[2025-04-20T21:05:52.211+0800] {processor.py:208} INFO - Processing /mnt/c/Users/wu_li/OneDrive/Desktop/Airflow_pract/dags/first_dag.py took 0.128 seconds
[2025-04-20T21:06:39.294+0800] {processor.py:186} INFO - Started process (PID=95396) to work on /mnt/c/Users/wu_li/OneDrive/Desktop/Airflow_pract/dags/first_dag.py
[2025-04-20T21:06:39.296+0800] {processor.py:914} INFO - Processing file /mnt/c/Users/wu_li/OneDrive/Desktop/Airflow_pract/dags/first_dag.py for tasks to queue
[2025-04-20T21:06:39.299+0800] {logging_mixin.py:190} INFO - [2025-04-20T21:06:39.298+0800] {dagbag.py:588} INFO - Filling up the DagBag from /mnt/c/Users/wu_li/OneDrive/Desktop/Airflow_pract/dags/first_dag.py
[2025-04-20T21:06:39.325+0800] {logging_mixin.py:190} INFO - [2025-04-20T21:06:39.316+0800] {dagbag.py:387} ERROR - Failed to import: /mnt/c/Users/wu_li/OneDrive/Desktop/Airflow_pract/dags/first_dag.py
Traceback (most recent call last):
  File "/mnt/c/Users/wu_li/OneDrive/Desktop/Airflow_pract/venv/lib/python3.9/site-packages/airflow/models/dagbag.py", line 383, in parse
    loader.exec_module(new_module)
  File "<frozen importlib._bootstrap_external>", line 850, in exec_module
  File "<frozen importlib._bootstrap>", line 228, in _call_with_frames_removed
  File "/mnt/c/Users/wu_li/OneDrive/Desktop/Airflow_pract/dags/first_dag.py", line 2, in <module>
    from airflow import first_dag
ImportError: cannot import name 'first_dag' from 'airflow' (/mnt/c/Users/wu_li/OneDrive/Desktop/Airflow_pract/venv/lib/python3.9/site-packages/airflow/__init__.py)
[2025-04-20T21:06:39.328+0800] {processor.py:927} WARNING - No viable dags retrieved from /mnt/c/Users/wu_li/OneDrive/Desktop/Airflow_pract/dags/first_dag.py
[2025-04-20T21:06:39.366+0800] {processor.py:208} INFO - Processing /mnt/c/Users/wu_li/OneDrive/Desktop/Airflow_pract/dags/first_dag.py took 0.084 seconds
[2025-04-20T21:07:26.836+0800] {processor.py:186} INFO - Started process (PID=95981) to work on /mnt/c/Users/wu_li/OneDrive/Desktop/Airflow_pract/dags/first_dag.py
[2025-04-20T21:07:26.838+0800] {processor.py:914} INFO - Processing file /mnt/c/Users/wu_li/OneDrive/Desktop/Airflow_pract/dags/first_dag.py for tasks to queue
[2025-04-20T21:07:26.840+0800] {logging_mixin.py:190} INFO - [2025-04-20T21:07:26.839+0800] {dagbag.py:588} INFO - Filling up the DagBag from /mnt/c/Users/wu_li/OneDrive/Desktop/Airflow_pract/dags/first_dag.py
[2025-04-20T21:07:26.865+0800] {logging_mixin.py:190} INFO - [2025-04-20T21:07:26.856+0800] {dagbag.py:387} ERROR - Failed to import: /mnt/c/Users/wu_li/OneDrive/Desktop/Airflow_pract/dags/first_dag.py
Traceback (most recent call last):
  File "/mnt/c/Users/wu_li/OneDrive/Desktop/Airflow_pract/venv/lib/python3.9/site-packages/airflow/models/dagbag.py", line 383, in parse
    loader.exec_module(new_module)
  File "<frozen importlib._bootstrap_external>", line 850, in exec_module
  File "<frozen importlib._bootstrap>", line 228, in _call_with_frames_removed
  File "/mnt/c/Users/wu_li/OneDrive/Desktop/Airflow_pract/dags/first_dag.py", line 2, in <module>
    from airflow import first_dag
ImportError: cannot import name 'first_dag' from 'airflow' (/mnt/c/Users/wu_li/OneDrive/Desktop/Airflow_pract/venv/lib/python3.9/site-packages/airflow/__init__.py)
[2025-04-20T21:07:26.867+0800] {processor.py:927} WARNING - No viable dags retrieved from /mnt/c/Users/wu_li/OneDrive/Desktop/Airflow_pract/dags/first_dag.py
[2025-04-20T21:07:26.903+0800] {processor.py:208} INFO - Processing /mnt/c/Users/wu_li/OneDrive/Desktop/Airflow_pract/dags/first_dag.py took 0.077 seconds
[2025-04-20T21:08:11.403+0800] {processor.py:186} INFO - Started process (PID=96550) to work on /mnt/c/Users/wu_li/OneDrive/Desktop/Airflow_pract/dags/first_dag.py
[2025-04-20T21:08:11.407+0800] {processor.py:914} INFO - Processing file /mnt/c/Users/wu_li/OneDrive/Desktop/Airflow_pract/dags/first_dag.py for tasks to queue
[2025-04-20T21:08:11.411+0800] {logging_mixin.py:190} INFO - [2025-04-20T21:08:11.410+0800] {dagbag.py:588} INFO - Filling up the DagBag from /mnt/c/Users/wu_li/OneDrive/Desktop/Airflow_pract/dags/first_dag.py
[2025-04-20T21:08:11.456+0800] {logging_mixin.py:190} INFO - [2025-04-20T21:08:11.444+0800] {dagbag.py:387} ERROR - Failed to import: /mnt/c/Users/wu_li/OneDrive/Desktop/Airflow_pract/dags/first_dag.py
Traceback (most recent call last):
  File "/mnt/c/Users/wu_li/OneDrive/Desktop/Airflow_pract/venv/lib/python3.9/site-packages/airflow/models/dagbag.py", line 383, in parse
    loader.exec_module(new_module)
  File "<frozen importlib._bootstrap_external>", line 850, in exec_module
  File "<frozen importlib._bootstrap>", line 228, in _call_with_frames_removed
  File "/mnt/c/Users/wu_li/OneDrive/Desktop/Airflow_pract/dags/first_dag.py", line 2, in <module>
    from airflow import first_dag
ImportError: cannot import name 'first_dag' from 'airflow' (/mnt/c/Users/wu_li/OneDrive/Desktop/Airflow_pract/venv/lib/python3.9/site-packages/airflow/__init__.py)
[2025-04-20T21:08:11.459+0800] {processor.py:927} WARNING - No viable dags retrieved from /mnt/c/Users/wu_li/OneDrive/Desktop/Airflow_pract/dags/first_dag.py
[2025-04-20T21:08:11.514+0800] {processor.py:208} INFO - Processing /mnt/c/Users/wu_li/OneDrive/Desktop/Airflow_pract/dags/first_dag.py took 0.130 seconds
[2025-04-20T21:08:57.744+0800] {processor.py:186} INFO - Started process (PID=97091) to work on /mnt/c/Users/wu_li/OneDrive/Desktop/Airflow_pract/dags/first_dag.py
[2025-04-20T21:08:57.749+0800] {processor.py:914} INFO - Processing file /mnt/c/Users/wu_li/OneDrive/Desktop/Airflow_pract/dags/first_dag.py for tasks to queue
[2025-04-20T21:08:57.754+0800] {logging_mixin.py:190} INFO - [2025-04-20T21:08:57.752+0800] {dagbag.py:588} INFO - Filling up the DagBag from /mnt/c/Users/wu_li/OneDrive/Desktop/Airflow_pract/dags/first_dag.py
[2025-04-20T21:08:57.799+0800] {logging_mixin.py:190} INFO - [2025-04-20T21:08:57.783+0800] {dagbag.py:387} ERROR - Failed to import: /mnt/c/Users/wu_li/OneDrive/Desktop/Airflow_pract/dags/first_dag.py
Traceback (most recent call last):
  File "/mnt/c/Users/wu_li/OneDrive/Desktop/Airflow_pract/venv/lib/python3.9/site-packages/airflow/models/dagbag.py", line 383, in parse
    loader.exec_module(new_module)
  File "<frozen importlib._bootstrap_external>", line 850, in exec_module
  File "<frozen importlib._bootstrap>", line 228, in _call_with_frames_removed
  File "/mnt/c/Users/wu_li/OneDrive/Desktop/Airflow_pract/dags/first_dag.py", line 2, in <module>
    from airflow import first_dag
ImportError: cannot import name 'first_dag' from 'airflow' (/mnt/c/Users/wu_li/OneDrive/Desktop/Airflow_pract/venv/lib/python3.9/site-packages/airflow/__init__.py)
[2025-04-20T21:08:57.805+0800] {processor.py:927} WARNING - No viable dags retrieved from /mnt/c/Users/wu_li/OneDrive/Desktop/Airflow_pract/dags/first_dag.py
[2025-04-20T21:08:57.876+0800] {processor.py:208} INFO - Processing /mnt/c/Users/wu_li/OneDrive/Desktop/Airflow_pract/dags/first_dag.py took 0.153 seconds
[2025-04-20T21:09:41.337+0800] {processor.py:186} INFO - Started process (PID=97560) to work on /mnt/c/Users/wu_li/OneDrive/Desktop/Airflow_pract/dags/first_dag.py
[2025-04-20T21:09:41.338+0800] {processor.py:914} INFO - Processing file /mnt/c/Users/wu_li/OneDrive/Desktop/Airflow_pract/dags/first_dag.py for tasks to queue
[2025-04-20T21:09:41.340+0800] {logging_mixin.py:190} INFO - [2025-04-20T21:09:41.339+0800] {dagbag.py:588} INFO - Filling up the DagBag from /mnt/c/Users/wu_li/OneDrive/Desktop/Airflow_pract/dags/first_dag.py
[2025-04-20T21:09:41.362+0800] {logging_mixin.py:190} INFO - [2025-04-20T21:09:41.354+0800] {dagbag.py:387} ERROR - Failed to import: /mnt/c/Users/wu_li/OneDrive/Desktop/Airflow_pract/dags/first_dag.py
Traceback (most recent call last):
  File "/mnt/c/Users/wu_li/OneDrive/Desktop/Airflow_pract/venv/lib/python3.9/site-packages/airflow/models/dagbag.py", line 383, in parse
    loader.exec_module(new_module)
  File "<frozen importlib._bootstrap_external>", line 850, in exec_module
  File "<frozen importlib._bootstrap>", line 228, in _call_with_frames_removed
  File "/mnt/c/Users/wu_li/OneDrive/Desktop/Airflow_pract/dags/first_dag.py", line 2, in <module>
    from airflow import first_dag
ImportError: cannot import name 'first_dag' from 'airflow' (/mnt/c/Users/wu_li/OneDrive/Desktop/Airflow_pract/venv/lib/python3.9/site-packages/airflow/__init__.py)
[2025-04-20T21:09:41.364+0800] {processor.py:927} WARNING - No viable dags retrieved from /mnt/c/Users/wu_li/OneDrive/Desktop/Airflow_pract/dags/first_dag.py
[2025-04-20T21:09:41.401+0800] {processor.py:208} INFO - Processing /mnt/c/Users/wu_li/OneDrive/Desktop/Airflow_pract/dags/first_dag.py took 0.075 seconds
[2025-04-20T21:10:26.077+0800] {processor.py:186} INFO - Started process (PID=98100) to work on /mnt/c/Users/wu_li/OneDrive/Desktop/Airflow_pract/dags/first_dag.py
[2025-04-20T21:10:26.079+0800] {processor.py:914} INFO - Processing file /mnt/c/Users/wu_li/OneDrive/Desktop/Airflow_pract/dags/first_dag.py for tasks to queue
[2025-04-20T21:10:26.081+0800] {logging_mixin.py:190} INFO - [2025-04-20T21:10:26.080+0800] {dagbag.py:588} INFO - Filling up the DagBag from /mnt/c/Users/wu_li/OneDrive/Desktop/Airflow_pract/dags/first_dag.py
[2025-04-20T21:10:26.106+0800] {logging_mixin.py:190} INFO - [2025-04-20T21:10:26.096+0800] {dagbag.py:387} ERROR - Failed to import: /mnt/c/Users/wu_li/OneDrive/Desktop/Airflow_pract/dags/first_dag.py
Traceback (most recent call last):
  File "/mnt/c/Users/wu_li/OneDrive/Desktop/Airflow_pract/venv/lib/python3.9/site-packages/airflow/models/dagbag.py", line 383, in parse
    loader.exec_module(new_module)
  File "<frozen importlib._bootstrap_external>", line 850, in exec_module
  File "<frozen importlib._bootstrap>", line 228, in _call_with_frames_removed
  File "/mnt/c/Users/wu_li/OneDrive/Desktop/Airflow_pract/dags/first_dag.py", line 2, in <module>
    from airflow import first_dag
ImportError: cannot import name 'first_dag' from 'airflow' (/mnt/c/Users/wu_li/OneDrive/Desktop/Airflow_pract/venv/lib/python3.9/site-packages/airflow/__init__.py)
[2025-04-20T21:10:26.108+0800] {processor.py:927} WARNING - No viable dags retrieved from /mnt/c/Users/wu_li/OneDrive/Desktop/Airflow_pract/dags/first_dag.py
[2025-04-20T21:10:26.148+0800] {processor.py:208} INFO - Processing /mnt/c/Users/wu_li/OneDrive/Desktop/Airflow_pract/dags/first_dag.py took 0.083 seconds
[2025-04-20T21:11:13.474+0800] {processor.py:186} INFO - Started process (PID=98710) to work on /mnt/c/Users/wu_li/OneDrive/Desktop/Airflow_pract/dags/first_dag.py
[2025-04-20T21:11:13.476+0800] {processor.py:914} INFO - Processing file /mnt/c/Users/wu_li/OneDrive/Desktop/Airflow_pract/dags/first_dag.py for tasks to queue
[2025-04-20T21:11:13.480+0800] {logging_mixin.py:190} INFO - [2025-04-20T21:11:13.478+0800] {dagbag.py:588} INFO - Filling up the DagBag from /mnt/c/Users/wu_li/OneDrive/Desktop/Airflow_pract/dags/first_dag.py
[2025-04-20T21:11:13.518+0800] {logging_mixin.py:190} INFO - [2025-04-20T21:11:13.504+0800] {dagbag.py:387} ERROR - Failed to import: /mnt/c/Users/wu_li/OneDrive/Desktop/Airflow_pract/dags/first_dag.py
Traceback (most recent call last):
  File "/mnt/c/Users/wu_li/OneDrive/Desktop/Airflow_pract/venv/lib/python3.9/site-packages/airflow/models/dagbag.py", line 383, in parse
    loader.exec_module(new_module)
  File "<frozen importlib._bootstrap_external>", line 850, in exec_module
  File "<frozen importlib._bootstrap>", line 228, in _call_with_frames_removed
  File "/mnt/c/Users/wu_li/OneDrive/Desktop/Airflow_pract/dags/first_dag.py", line 2, in <module>
    from airflow import first_dag
ImportError: cannot import name 'first_dag' from 'airflow' (/mnt/c/Users/wu_li/OneDrive/Desktop/Airflow_pract/venv/lib/python3.9/site-packages/airflow/__init__.py)
[2025-04-20T21:11:13.521+0800] {processor.py:927} WARNING - No viable dags retrieved from /mnt/c/Users/wu_li/OneDrive/Desktop/Airflow_pract/dags/first_dag.py
[2025-04-20T21:11:13.585+0800] {processor.py:208} INFO - Processing /mnt/c/Users/wu_li/OneDrive/Desktop/Airflow_pract/dags/first_dag.py took 0.129 seconds
[2025-04-20T21:11:59.625+0800] {processor.py:186} INFO - Started process (PID=99253) to work on /mnt/c/Users/wu_li/OneDrive/Desktop/Airflow_pract/dags/first_dag.py
[2025-04-20T21:11:59.629+0800] {processor.py:914} INFO - Processing file /mnt/c/Users/wu_li/OneDrive/Desktop/Airflow_pract/dags/first_dag.py for tasks to queue
[2025-04-20T21:11:59.633+0800] {logging_mixin.py:190} INFO - [2025-04-20T21:11:59.631+0800] {dagbag.py:588} INFO - Filling up the DagBag from /mnt/c/Users/wu_li/OneDrive/Desktop/Airflow_pract/dags/first_dag.py
[2025-04-20T21:11:59.676+0800] {logging_mixin.py:190} INFO - [2025-04-20T21:11:59.661+0800] {dagbag.py:387} ERROR - Failed to import: /mnt/c/Users/wu_li/OneDrive/Desktop/Airflow_pract/dags/first_dag.py
Traceback (most recent call last):
  File "/mnt/c/Users/wu_li/OneDrive/Desktop/Airflow_pract/venv/lib/python3.9/site-packages/airflow/models/dagbag.py", line 383, in parse
    loader.exec_module(new_module)
  File "<frozen importlib._bootstrap_external>", line 850, in exec_module
  File "<frozen importlib._bootstrap>", line 228, in _call_with_frames_removed
  File "/mnt/c/Users/wu_li/OneDrive/Desktop/Airflow_pract/dags/first_dag.py", line 2, in <module>
    from airflow import first_dag
ImportError: cannot import name 'first_dag' from 'airflow' (/mnt/c/Users/wu_li/OneDrive/Desktop/Airflow_pract/venv/lib/python3.9/site-packages/airflow/__init__.py)
[2025-04-20T21:11:59.679+0800] {processor.py:927} WARNING - No viable dags retrieved from /mnt/c/Users/wu_li/OneDrive/Desktop/Airflow_pract/dags/first_dag.py
[2025-04-20T21:11:59.735+0800] {processor.py:208} INFO - Processing /mnt/c/Users/wu_li/OneDrive/Desktop/Airflow_pract/dags/first_dag.py took 0.132 seconds
[2025-04-20T21:12:44.807+0800] {processor.py:186} INFO - Started process (PID=99793) to work on /mnt/c/Users/wu_li/OneDrive/Desktop/Airflow_pract/dags/first_dag.py
[2025-04-20T21:12:44.810+0800] {processor.py:914} INFO - Processing file /mnt/c/Users/wu_li/OneDrive/Desktop/Airflow_pract/dags/first_dag.py for tasks to queue
[2025-04-20T21:12:44.815+0800] {logging_mixin.py:190} INFO - [2025-04-20T21:12:44.813+0800] {dagbag.py:588} INFO - Filling up the DagBag from /mnt/c/Users/wu_li/OneDrive/Desktop/Airflow_pract/dags/first_dag.py
[2025-04-20T21:12:44.856+0800] {logging_mixin.py:190} INFO - [2025-04-20T21:12:44.843+0800] {dagbag.py:387} ERROR - Failed to import: /mnt/c/Users/wu_li/OneDrive/Desktop/Airflow_pract/dags/first_dag.py
Traceback (most recent call last):
  File "/mnt/c/Users/wu_li/OneDrive/Desktop/Airflow_pract/venv/lib/python3.9/site-packages/airflow/models/dagbag.py", line 383, in parse
    loader.exec_module(new_module)
  File "<frozen importlib._bootstrap_external>", line 850, in exec_module
  File "<frozen importlib._bootstrap>", line 228, in _call_with_frames_removed
  File "/mnt/c/Users/wu_li/OneDrive/Desktop/Airflow_pract/dags/first_dag.py", line 2, in <module>
    from airflow import first_dag
ImportError: cannot import name 'first_dag' from 'airflow' (/mnt/c/Users/wu_li/OneDrive/Desktop/Airflow_pract/venv/lib/python3.9/site-packages/airflow/__init__.py)
[2025-04-20T21:12:44.859+0800] {processor.py:927} WARNING - No viable dags retrieved from /mnt/c/Users/wu_li/OneDrive/Desktop/Airflow_pract/dags/first_dag.py
[2025-04-20T21:12:44.941+0800] {processor.py:208} INFO - Processing /mnt/c/Users/wu_li/OneDrive/Desktop/Airflow_pract/dags/first_dag.py took 0.155 seconds
[2025-04-20T21:13:29.642+0800] {processor.py:186} INFO - Started process (PID=100333) to work on /mnt/c/Users/wu_li/OneDrive/Desktop/Airflow_pract/dags/first_dag.py
[2025-04-20T21:13:29.644+0800] {processor.py:914} INFO - Processing file /mnt/c/Users/wu_li/OneDrive/Desktop/Airflow_pract/dags/first_dag.py for tasks to queue
[2025-04-20T21:13:29.648+0800] {logging_mixin.py:190} INFO - [2025-04-20T21:13:29.647+0800] {dagbag.py:588} INFO - Filling up the DagBag from /mnt/c/Users/wu_li/OneDrive/Desktop/Airflow_pract/dags/first_dag.py
[2025-04-20T21:13:29.689+0800] {logging_mixin.py:190} INFO - [2025-04-20T21:13:29.676+0800] {dagbag.py:387} ERROR - Failed to import: /mnt/c/Users/wu_li/OneDrive/Desktop/Airflow_pract/dags/first_dag.py
Traceback (most recent call last):
  File "/mnt/c/Users/wu_li/OneDrive/Desktop/Airflow_pract/venv/lib/python3.9/site-packages/airflow/models/dagbag.py", line 383, in parse
    loader.exec_module(new_module)
  File "<frozen importlib._bootstrap_external>", line 850, in exec_module
  File "<frozen importlib._bootstrap>", line 228, in _call_with_frames_removed
  File "/mnt/c/Users/wu_li/OneDrive/Desktop/Airflow_pract/dags/first_dag.py", line 2, in <module>
    from airflow import first_dag
ImportError: cannot import name 'first_dag' from 'airflow' (/mnt/c/Users/wu_li/OneDrive/Desktop/Airflow_pract/venv/lib/python3.9/site-packages/airflow/__init__.py)
[2025-04-20T21:13:29.692+0800] {processor.py:927} WARNING - No viable dags retrieved from /mnt/c/Users/wu_li/OneDrive/Desktop/Airflow_pract/dags/first_dag.py
[2025-04-20T21:13:29.763+0800] {processor.py:208} INFO - Processing /mnt/c/Users/wu_li/OneDrive/Desktop/Airflow_pract/dags/first_dag.py took 0.141 seconds
[2025-04-20T21:14:15.332+0800] {processor.py:186} INFO - Started process (PID=100799) to work on /mnt/c/Users/wu_li/OneDrive/Desktop/Airflow_pract/dags/first_dag.py
[2025-04-20T21:14:15.334+0800] {processor.py:914} INFO - Processing file /mnt/c/Users/wu_li/OneDrive/Desktop/Airflow_pract/dags/first_dag.py for tasks to queue
[2025-04-20T21:14:15.339+0800] {logging_mixin.py:190} INFO - [2025-04-20T21:14:15.338+0800] {dagbag.py:588} INFO - Filling up the DagBag from /mnt/c/Users/wu_li/OneDrive/Desktop/Airflow_pract/dags/first_dag.py
[2025-04-20T21:14:15.376+0800] {logging_mixin.py:190} INFO - [2025-04-20T21:14:15.362+0800] {dagbag.py:387} ERROR - Failed to import: /mnt/c/Users/wu_li/OneDrive/Desktop/Airflow_pract/dags/first_dag.py
Traceback (most recent call last):
  File "/mnt/c/Users/wu_li/OneDrive/Desktop/Airflow_pract/venv/lib/python3.9/site-packages/airflow/models/dagbag.py", line 383, in parse
    loader.exec_module(new_module)
  File "<frozen importlib._bootstrap_external>", line 850, in exec_module
  File "<frozen importlib._bootstrap>", line 228, in _call_with_frames_removed
  File "/mnt/c/Users/wu_li/OneDrive/Desktop/Airflow_pract/dags/first_dag.py", line 2, in <module>
    from airflow import first_dag
ImportError: cannot import name 'first_dag' from 'airflow' (/mnt/c/Users/wu_li/OneDrive/Desktop/Airflow_pract/venv/lib/python3.9/site-packages/airflow/__init__.py)
[2025-04-20T21:14:15.379+0800] {processor.py:927} WARNING - No viable dags retrieved from /mnt/c/Users/wu_li/OneDrive/Desktop/Airflow_pract/dags/first_dag.py
[2025-04-20T21:14:15.436+0800] {processor.py:208} INFO - Processing /mnt/c/Users/wu_li/OneDrive/Desktop/Airflow_pract/dags/first_dag.py took 0.123 seconds
[2025-04-20T21:15:00.479+0800] {processor.py:186} INFO - Started process (PID=101341) to work on /mnt/c/Users/wu_li/OneDrive/Desktop/Airflow_pract/dags/first_dag.py
[2025-04-20T21:15:00.484+0800] {processor.py:914} INFO - Processing file /mnt/c/Users/wu_li/OneDrive/Desktop/Airflow_pract/dags/first_dag.py for tasks to queue
[2025-04-20T21:15:00.488+0800] {logging_mixin.py:190} INFO - [2025-04-20T21:15:00.487+0800] {dagbag.py:588} INFO - Filling up the DagBag from /mnt/c/Users/wu_li/OneDrive/Desktop/Airflow_pract/dags/first_dag.py
[2025-04-20T21:15:00.547+0800] {logging_mixin.py:190} INFO - [2025-04-20T21:15:00.530+0800] {dagbag.py:387} ERROR - Failed to import: /mnt/c/Users/wu_li/OneDrive/Desktop/Airflow_pract/dags/first_dag.py
Traceback (most recent call last):
  File "/mnt/c/Users/wu_li/OneDrive/Desktop/Airflow_pract/venv/lib/python3.9/site-packages/airflow/models/dagbag.py", line 383, in parse
    loader.exec_module(new_module)
  File "<frozen importlib._bootstrap_external>", line 850, in exec_module
  File "<frozen importlib._bootstrap>", line 228, in _call_with_frames_removed
  File "/mnt/c/Users/wu_li/OneDrive/Desktop/Airflow_pract/dags/first_dag.py", line 2, in <module>
    from airflow import first_dag
ImportError: cannot import name 'first_dag' from 'airflow' (/mnt/c/Users/wu_li/OneDrive/Desktop/Airflow_pract/venv/lib/python3.9/site-packages/airflow/__init__.py)
[2025-04-20T21:15:00.555+0800] {processor.py:927} WARNING - No viable dags retrieved from /mnt/c/Users/wu_li/OneDrive/Desktop/Airflow_pract/dags/first_dag.py
[2025-04-20T21:15:00.625+0800] {processor.py:208} INFO - Processing /mnt/c/Users/wu_li/OneDrive/Desktop/Airflow_pract/dags/first_dag.py took 0.173 seconds
[2025-04-20T21:15:44.493+0800] {processor.py:186} INFO - Started process (PID=101878) to work on /mnt/c/Users/wu_li/OneDrive/Desktop/Airflow_pract/dags/first_dag.py
[2025-04-20T21:15:44.495+0800] {processor.py:914} INFO - Processing file /mnt/c/Users/wu_li/OneDrive/Desktop/Airflow_pract/dags/first_dag.py for tasks to queue
[2025-04-20T21:15:44.498+0800] {logging_mixin.py:190} INFO - [2025-04-20T21:15:44.497+0800] {dagbag.py:588} INFO - Filling up the DagBag from /mnt/c/Users/wu_li/OneDrive/Desktop/Airflow_pract/dags/first_dag.py
[2025-04-20T21:15:44.519+0800] {logging_mixin.py:190} INFO - [2025-04-20T21:15:44.511+0800] {dagbag.py:387} ERROR - Failed to import: /mnt/c/Users/wu_li/OneDrive/Desktop/Airflow_pract/dags/first_dag.py
Traceback (most recent call last):
  File "/mnt/c/Users/wu_li/OneDrive/Desktop/Airflow_pract/venv/lib/python3.9/site-packages/airflow/models/dagbag.py", line 383, in parse
    loader.exec_module(new_module)
  File "<frozen importlib._bootstrap_external>", line 850, in exec_module
  File "<frozen importlib._bootstrap>", line 228, in _call_with_frames_removed
  File "/mnt/c/Users/wu_li/OneDrive/Desktop/Airflow_pract/dags/first_dag.py", line 2, in <module>
    from airflow import first_dag
ImportError: cannot import name 'first_dag' from 'airflow' (/mnt/c/Users/wu_li/OneDrive/Desktop/Airflow_pract/venv/lib/python3.9/site-packages/airflow/__init__.py)
[2025-04-20T21:15:44.521+0800] {processor.py:927} WARNING - No viable dags retrieved from /mnt/c/Users/wu_li/OneDrive/Desktop/Airflow_pract/dags/first_dag.py
[2025-04-20T21:15:44.587+0800] {processor.py:208} INFO - Processing /mnt/c/Users/wu_li/OneDrive/Desktop/Airflow_pract/dags/first_dag.py took 0.114 seconds
[2025-04-20T21:16:31.863+0800] {processor.py:186} INFO - Started process (PID=102421) to work on /mnt/c/Users/wu_li/OneDrive/Desktop/Airflow_pract/dags/first_dag.py
[2025-04-20T21:16:31.866+0800] {processor.py:914} INFO - Processing file /mnt/c/Users/wu_li/OneDrive/Desktop/Airflow_pract/dags/first_dag.py for tasks to queue
[2025-04-20T21:16:31.870+0800] {logging_mixin.py:190} INFO - [2025-04-20T21:16:31.869+0800] {dagbag.py:588} INFO - Filling up the DagBag from /mnt/c/Users/wu_li/OneDrive/Desktop/Airflow_pract/dags/first_dag.py
[2025-04-20T21:16:31.928+0800] {logging_mixin.py:190} INFO - [2025-04-20T21:16:31.902+0800] {dagbag.py:387} ERROR - Failed to import: /mnt/c/Users/wu_li/OneDrive/Desktop/Airflow_pract/dags/first_dag.py
Traceback (most recent call last):
  File "/mnt/c/Users/wu_li/OneDrive/Desktop/Airflow_pract/venv/lib/python3.9/site-packages/airflow/models/dagbag.py", line 383, in parse
    loader.exec_module(new_module)
  File "<frozen importlib._bootstrap_external>", line 850, in exec_module
  File "<frozen importlib._bootstrap>", line 228, in _call_with_frames_removed
  File "/mnt/c/Users/wu_li/OneDrive/Desktop/Airflow_pract/dags/first_dag.py", line 2, in <module>
    from airflow import first_dag
ImportError: cannot import name 'first_dag' from 'airflow' (/mnt/c/Users/wu_li/OneDrive/Desktop/Airflow_pract/venv/lib/python3.9/site-packages/airflow/__init__.py)
[2025-04-20T21:16:31.932+0800] {processor.py:927} WARNING - No viable dags retrieved from /mnt/c/Users/wu_li/OneDrive/Desktop/Airflow_pract/dags/first_dag.py
[2025-04-20T21:16:32.040+0800] {processor.py:208} INFO - Processing /mnt/c/Users/wu_li/OneDrive/Desktop/Airflow_pract/dags/first_dag.py took 0.195 seconds
[2025-04-20T21:17:14.826+0800] {processor.py:186} INFO - Started process (PID=102892) to work on /mnt/c/Users/wu_li/OneDrive/Desktop/Airflow_pract/dags/first_dag.py
[2025-04-20T21:17:14.828+0800] {processor.py:914} INFO - Processing file /mnt/c/Users/wu_li/OneDrive/Desktop/Airflow_pract/dags/first_dag.py for tasks to queue
[2025-04-20T21:17:14.832+0800] {logging_mixin.py:190} INFO - [2025-04-20T21:17:14.831+0800] {dagbag.py:588} INFO - Filling up the DagBag from /mnt/c/Users/wu_li/OneDrive/Desktop/Airflow_pract/dags/first_dag.py
[2025-04-20T21:17:14.869+0800] {logging_mixin.py:190} INFO - [2025-04-20T21:17:14.856+0800] {dagbag.py:387} ERROR - Failed to import: /mnt/c/Users/wu_li/OneDrive/Desktop/Airflow_pract/dags/first_dag.py
Traceback (most recent call last):
  File "/mnt/c/Users/wu_li/OneDrive/Desktop/Airflow_pract/venv/lib/python3.9/site-packages/airflow/models/dagbag.py", line 383, in parse
    loader.exec_module(new_module)
  File "<frozen importlib._bootstrap_external>", line 850, in exec_module
  File "<frozen importlib._bootstrap>", line 228, in _call_with_frames_removed
  File "/mnt/c/Users/wu_li/OneDrive/Desktop/Airflow_pract/dags/first_dag.py", line 2, in <module>
    from airflow import first_dag
ImportError: cannot import name 'first_dag' from 'airflow' (/mnt/c/Users/wu_li/OneDrive/Desktop/Airflow_pract/venv/lib/python3.9/site-packages/airflow/__init__.py)
[2025-04-20T21:17:14.872+0800] {processor.py:927} WARNING - No viable dags retrieved from /mnt/c/Users/wu_li/OneDrive/Desktop/Airflow_pract/dags/first_dag.py
[2025-04-20T21:17:14.933+0800] {processor.py:208} INFO - Processing /mnt/c/Users/wu_li/OneDrive/Desktop/Airflow_pract/dags/first_dag.py took 0.125 seconds
[2025-04-20T21:17:57.466+0800] {processor.py:186} INFO - Started process (PID=103431) to work on /mnt/c/Users/wu_li/OneDrive/Desktop/Airflow_pract/dags/first_dag.py
[2025-04-20T21:17:57.470+0800] {processor.py:914} INFO - Processing file /mnt/c/Users/wu_li/OneDrive/Desktop/Airflow_pract/dags/first_dag.py for tasks to queue
[2025-04-20T21:17:57.484+0800] {logging_mixin.py:190} INFO - [2025-04-20T21:17:57.480+0800] {dagbag.py:588} INFO - Filling up the DagBag from /mnt/c/Users/wu_li/OneDrive/Desktop/Airflow_pract/dags/first_dag.py
[2025-04-20T21:17:57.544+0800] {logging_mixin.py:190} INFO - [2025-04-20T21:17:57.527+0800] {dagbag.py:387} ERROR - Failed to import: /mnt/c/Users/wu_li/OneDrive/Desktop/Airflow_pract/dags/first_dag.py
Traceback (most recent call last):
  File "/mnt/c/Users/wu_li/OneDrive/Desktop/Airflow_pract/venv/lib/python3.9/site-packages/airflow/models/dagbag.py", line 383, in parse
    loader.exec_module(new_module)
  File "<frozen importlib._bootstrap_external>", line 850, in exec_module
  File "<frozen importlib._bootstrap>", line 228, in _call_with_frames_removed
  File "/mnt/c/Users/wu_li/OneDrive/Desktop/Airflow_pract/dags/first_dag.py", line 2, in <module>
    from airflow import first_dag
ImportError: cannot import name 'first_dag' from 'airflow' (/mnt/c/Users/wu_li/OneDrive/Desktop/Airflow_pract/venv/lib/python3.9/site-packages/airflow/__init__.py)
[2025-04-20T21:17:57.550+0800] {processor.py:927} WARNING - No viable dags retrieved from /mnt/c/Users/wu_li/OneDrive/Desktop/Airflow_pract/dags/first_dag.py
[2025-04-20T21:17:57.616+0800] {processor.py:208} INFO - Processing /mnt/c/Users/wu_li/OneDrive/Desktop/Airflow_pract/dags/first_dag.py took 0.168 seconds
[2025-04-20T21:18:40.677+0800] {processor.py:186} INFO - Started process (PID=103896) to work on /mnt/c/Users/wu_li/OneDrive/Desktop/Airflow_pract/dags/first_dag.py
[2025-04-20T21:18:40.680+0800] {processor.py:914} INFO - Processing file /mnt/c/Users/wu_li/OneDrive/Desktop/Airflow_pract/dags/first_dag.py for tasks to queue
[2025-04-20T21:18:40.685+0800] {logging_mixin.py:190} INFO - [2025-04-20T21:18:40.683+0800] {dagbag.py:588} INFO - Filling up the DagBag from /mnt/c/Users/wu_li/OneDrive/Desktop/Airflow_pract/dags/first_dag.py
[2025-04-20T21:18:40.724+0800] {logging_mixin.py:190} INFO - [2025-04-20T21:18:40.711+0800] {dagbag.py:387} ERROR - Failed to import: /mnt/c/Users/wu_li/OneDrive/Desktop/Airflow_pract/dags/first_dag.py
Traceback (most recent call last):
  File "/mnt/c/Users/wu_li/OneDrive/Desktop/Airflow_pract/venv/lib/python3.9/site-packages/airflow/models/dagbag.py", line 383, in parse
    loader.exec_module(new_module)
  File "<frozen importlib._bootstrap_external>", line 850, in exec_module
  File "<frozen importlib._bootstrap>", line 228, in _call_with_frames_removed
  File "/mnt/c/Users/wu_li/OneDrive/Desktop/Airflow_pract/dags/first_dag.py", line 2, in <module>
    from airflow import first_dag
ImportError: cannot import name 'first_dag' from 'airflow' (/mnt/c/Users/wu_li/OneDrive/Desktop/Airflow_pract/venv/lib/python3.9/site-packages/airflow/__init__.py)
[2025-04-20T21:18:40.728+0800] {processor.py:927} WARNING - No viable dags retrieved from /mnt/c/Users/wu_li/OneDrive/Desktop/Airflow_pract/dags/first_dag.py
[2025-04-20T21:18:40.818+0800] {processor.py:208} INFO - Processing /mnt/c/Users/wu_li/OneDrive/Desktop/Airflow_pract/dags/first_dag.py took 0.164 seconds
[2025-04-20T21:19:24.584+0800] {processor.py:186} INFO - Started process (PID=104436) to work on /mnt/c/Users/wu_li/OneDrive/Desktop/Airflow_pract/dags/first_dag.py
[2025-04-20T21:19:24.589+0800] {processor.py:914} INFO - Processing file /mnt/c/Users/wu_li/OneDrive/Desktop/Airflow_pract/dags/first_dag.py for tasks to queue
[2025-04-20T21:19:24.593+0800] {logging_mixin.py:190} INFO - [2025-04-20T21:19:24.591+0800] {dagbag.py:588} INFO - Filling up the DagBag from /mnt/c/Users/wu_li/OneDrive/Desktop/Airflow_pract/dags/first_dag.py
[2025-04-20T21:19:24.629+0800] {logging_mixin.py:190} INFO - [2025-04-20T21:19:24.617+0800] {dagbag.py:387} ERROR - Failed to import: /mnt/c/Users/wu_li/OneDrive/Desktop/Airflow_pract/dags/first_dag.py
Traceback (most recent call last):
  File "/mnt/c/Users/wu_li/OneDrive/Desktop/Airflow_pract/venv/lib/python3.9/site-packages/airflow/models/dagbag.py", line 383, in parse
    loader.exec_module(new_module)
  File "<frozen importlib._bootstrap_external>", line 850, in exec_module
  File "<frozen importlib._bootstrap>", line 228, in _call_with_frames_removed
  File "/mnt/c/Users/wu_li/OneDrive/Desktop/Airflow_pract/dags/first_dag.py", line 2, in <module>
    from airflow import first_dag
ImportError: cannot import name 'first_dag' from 'airflow' (/mnt/c/Users/wu_li/OneDrive/Desktop/Airflow_pract/venv/lib/python3.9/site-packages/airflow/__init__.py)
[2025-04-20T21:19:24.633+0800] {processor.py:927} WARNING - No viable dags retrieved from /mnt/c/Users/wu_li/OneDrive/Desktop/Airflow_pract/dags/first_dag.py
[2025-04-20T21:19:24.691+0800] {processor.py:208} INFO - Processing /mnt/c/Users/wu_li/OneDrive/Desktop/Airflow_pract/dags/first_dag.py took 0.128 seconds
[2025-04-20T21:20:10.052+0800] {processor.py:186} INFO - Started process (PID=104906) to work on /mnt/c/Users/wu_li/OneDrive/Desktop/Airflow_pract/dags/first_dag.py
[2025-04-20T21:20:10.053+0800] {processor.py:914} INFO - Processing file /mnt/c/Users/wu_li/OneDrive/Desktop/Airflow_pract/dags/first_dag.py for tasks to queue
[2025-04-20T21:20:10.056+0800] {logging_mixin.py:190} INFO - [2025-04-20T21:20:10.055+0800] {dagbag.py:588} INFO - Filling up the DagBag from /mnt/c/Users/wu_li/OneDrive/Desktop/Airflow_pract/dags/first_dag.py
[2025-04-20T21:20:10.079+0800] {logging_mixin.py:190} INFO - [2025-04-20T21:20:10.070+0800] {dagbag.py:387} ERROR - Failed to import: /mnt/c/Users/wu_li/OneDrive/Desktop/Airflow_pract/dags/first_dag.py
Traceback (most recent call last):
  File "/mnt/c/Users/wu_li/OneDrive/Desktop/Airflow_pract/venv/lib/python3.9/site-packages/airflow/models/dagbag.py", line 383, in parse
    loader.exec_module(new_module)
  File "<frozen importlib._bootstrap_external>", line 850, in exec_module
  File "<frozen importlib._bootstrap>", line 228, in _call_with_frames_removed
  File "/mnt/c/Users/wu_li/OneDrive/Desktop/Airflow_pract/dags/first_dag.py", line 2, in <module>
    from airflow import first_dag
ImportError: cannot import name 'first_dag' from 'airflow' (/mnt/c/Users/wu_li/OneDrive/Desktop/Airflow_pract/venv/lib/python3.9/site-packages/airflow/__init__.py)
[2025-04-20T21:20:10.083+0800] {processor.py:927} WARNING - No viable dags retrieved from /mnt/c/Users/wu_li/OneDrive/Desktop/Airflow_pract/dags/first_dag.py
[2025-04-20T21:20:10.119+0800] {processor.py:208} INFO - Processing /mnt/c/Users/wu_li/OneDrive/Desktop/Airflow_pract/dags/first_dag.py took 0.077 seconds
[2025-04-20T21:20:55.212+0800] {processor.py:186} INFO - Started process (PID=105445) to work on /mnt/c/Users/wu_li/OneDrive/Desktop/Airflow_pract/dags/first_dag.py
[2025-04-20T21:20:55.213+0800] {processor.py:914} INFO - Processing file /mnt/c/Users/wu_li/OneDrive/Desktop/Airflow_pract/dags/first_dag.py for tasks to queue
[2025-04-20T21:20:55.216+0800] {logging_mixin.py:190} INFO - [2025-04-20T21:20:55.215+0800] {dagbag.py:588} INFO - Filling up the DagBag from /mnt/c/Users/wu_li/OneDrive/Desktop/Airflow_pract/dags/first_dag.py
[2025-04-20T21:20:55.239+0800] {logging_mixin.py:190} INFO - [2025-04-20T21:20:55.230+0800] {dagbag.py:387} ERROR - Failed to import: /mnt/c/Users/wu_li/OneDrive/Desktop/Airflow_pract/dags/first_dag.py
Traceback (most recent call last):
  File "/mnt/c/Users/wu_li/OneDrive/Desktop/Airflow_pract/venv/lib/python3.9/site-packages/airflow/models/dagbag.py", line 383, in parse
    loader.exec_module(new_module)
  File "<frozen importlib._bootstrap_external>", line 850, in exec_module
  File "<frozen importlib._bootstrap>", line 228, in _call_with_frames_removed
  File "/mnt/c/Users/wu_li/OneDrive/Desktop/Airflow_pract/dags/first_dag.py", line 2, in <module>
    from airflow import first_dag
ImportError: cannot import name 'first_dag' from 'airflow' (/mnt/c/Users/wu_li/OneDrive/Desktop/Airflow_pract/venv/lib/python3.9/site-packages/airflow/__init__.py)
[2025-04-20T21:20:55.242+0800] {processor.py:927} WARNING - No viable dags retrieved from /mnt/c/Users/wu_li/OneDrive/Desktop/Airflow_pract/dags/first_dag.py
[2025-04-20T21:20:55.288+0800] {processor.py:208} INFO - Processing /mnt/c/Users/wu_li/OneDrive/Desktop/Airflow_pract/dags/first_dag.py took 0.088 seconds
[2025-04-20T21:21:42.062+0800] {processor.py:186} INFO - Started process (PID=106024) to work on /mnt/c/Users/wu_li/OneDrive/Desktop/Airflow_pract/dags/first_dag.py
[2025-04-20T21:21:42.064+0800] {processor.py:914} INFO - Processing file /mnt/c/Users/wu_li/OneDrive/Desktop/Airflow_pract/dags/first_dag.py for tasks to queue
[2025-04-20T21:21:42.066+0800] {logging_mixin.py:190} INFO - [2025-04-20T21:21:42.065+0800] {dagbag.py:588} INFO - Filling up the DagBag from /mnt/c/Users/wu_li/OneDrive/Desktop/Airflow_pract/dags/first_dag.py
[2025-04-20T21:21:42.092+0800] {logging_mixin.py:190} INFO - [2025-04-20T21:21:42.083+0800] {dagbag.py:387} ERROR - Failed to import: /mnt/c/Users/wu_li/OneDrive/Desktop/Airflow_pract/dags/first_dag.py
Traceback (most recent call last):
  File "/mnt/c/Users/wu_li/OneDrive/Desktop/Airflow_pract/venv/lib/python3.9/site-packages/airflow/models/dagbag.py", line 383, in parse
    loader.exec_module(new_module)
  File "<frozen importlib._bootstrap_external>", line 850, in exec_module
  File "<frozen importlib._bootstrap>", line 228, in _call_with_frames_removed
  File "/mnt/c/Users/wu_li/OneDrive/Desktop/Airflow_pract/dags/first_dag.py", line 2, in <module>
    from airflow import first_dag
ImportError: cannot import name 'first_dag' from 'airflow' (/mnt/c/Users/wu_li/OneDrive/Desktop/Airflow_pract/venv/lib/python3.9/site-packages/airflow/__init__.py)
[2025-04-20T21:21:42.094+0800] {processor.py:927} WARNING - No viable dags retrieved from /mnt/c/Users/wu_li/OneDrive/Desktop/Airflow_pract/dags/first_dag.py
[2025-04-20T21:21:42.137+0800] {processor.py:208} INFO - Processing /mnt/c/Users/wu_li/OneDrive/Desktop/Airflow_pract/dags/first_dag.py took 0.087 seconds
[2025-04-20T21:22:27.715+0800] {processor.py:186} INFO - Started process (PID=106565) to work on /mnt/c/Users/wu_li/OneDrive/Desktop/Airflow_pract/dags/first_dag.py
[2025-04-20T21:22:27.717+0800] {processor.py:914} INFO - Processing file /mnt/c/Users/wu_li/OneDrive/Desktop/Airflow_pract/dags/first_dag.py for tasks to queue
[2025-04-20T21:22:27.720+0800] {logging_mixin.py:190} INFO - [2025-04-20T21:22:27.719+0800] {dagbag.py:588} INFO - Filling up the DagBag from /mnt/c/Users/wu_li/OneDrive/Desktop/Airflow_pract/dags/first_dag.py
[2025-04-20T21:22:27.740+0800] {logging_mixin.py:190} INFO - [2025-04-20T21:22:27.733+0800] {dagbag.py:387} ERROR - Failed to import: /mnt/c/Users/wu_li/OneDrive/Desktop/Airflow_pract/dags/first_dag.py
Traceback (most recent call last):
  File "/mnt/c/Users/wu_li/OneDrive/Desktop/Airflow_pract/venv/lib/python3.9/site-packages/airflow/models/dagbag.py", line 383, in parse
    loader.exec_module(new_module)
  File "<frozen importlib._bootstrap_external>", line 850, in exec_module
  File "<frozen importlib._bootstrap>", line 228, in _call_with_frames_removed
  File "/mnt/c/Users/wu_li/OneDrive/Desktop/Airflow_pract/dags/first_dag.py", line 2, in <module>
    from airflow import first_dag
ImportError: cannot import name 'first_dag' from 'airflow' (/mnt/c/Users/wu_li/OneDrive/Desktop/Airflow_pract/venv/lib/python3.9/site-packages/airflow/__init__.py)
[2025-04-20T21:22:27.742+0800] {processor.py:927} WARNING - No viable dags retrieved from /mnt/c/Users/wu_li/OneDrive/Desktop/Airflow_pract/dags/first_dag.py
[2025-04-20T21:22:27.787+0800] {processor.py:208} INFO - Processing /mnt/c/Users/wu_li/OneDrive/Desktop/Airflow_pract/dags/first_dag.py took 0.083 seconds
[2025-04-20T21:23:15.194+0800] {processor.py:186} INFO - Started process (PID=106992) to work on /mnt/c/Users/wu_li/OneDrive/Desktop/Airflow_pract/dags/first_dag.py
[2025-04-20T21:23:15.196+0800] {processor.py:914} INFO - Processing file /mnt/c/Users/wu_li/OneDrive/Desktop/Airflow_pract/dags/first_dag.py for tasks to queue
[2025-04-20T21:23:15.201+0800] {logging_mixin.py:190} INFO - [2025-04-20T21:23:15.199+0800] {dagbag.py:588} INFO - Filling up the DagBag from /mnt/c/Users/wu_li/OneDrive/Desktop/Airflow_pract/dags/first_dag.py
[2025-04-20T21:23:15.238+0800] {logging_mixin.py:190} INFO - [2025-04-20T21:23:15.225+0800] {dagbag.py:387} ERROR - Failed to import: /mnt/c/Users/wu_li/OneDrive/Desktop/Airflow_pract/dags/first_dag.py
Traceback (most recent call last):
  File "/mnt/c/Users/wu_li/OneDrive/Desktop/Airflow_pract/venv/lib/python3.9/site-packages/airflow/models/dagbag.py", line 383, in parse
    loader.exec_module(new_module)
  File "<frozen importlib._bootstrap_external>", line 850, in exec_module
  File "<frozen importlib._bootstrap>", line 228, in _call_with_frames_removed
  File "/mnt/c/Users/wu_li/OneDrive/Desktop/Airflow_pract/dags/first_dag.py", line 2, in <module>
    from airflow import first_dag
ImportError: cannot import name 'first_dag' from 'airflow' (/mnt/c/Users/wu_li/OneDrive/Desktop/Airflow_pract/venv/lib/python3.9/site-packages/airflow/__init__.py)
[2025-04-20T21:23:15.241+0800] {processor.py:927} WARNING - No viable dags retrieved from /mnt/c/Users/wu_li/OneDrive/Desktop/Airflow_pract/dags/first_dag.py
[2025-04-20T21:23:15.304+0800] {processor.py:208} INFO - Processing /mnt/c/Users/wu_li/OneDrive/Desktop/Airflow_pract/dags/first_dag.py took 0.128 seconds
[2025-04-20T21:23:59.431+0800] {processor.py:186} INFO - Started process (PID=107463) to work on /mnt/c/Users/wu_li/OneDrive/Desktop/Airflow_pract/dags/first_dag.py
[2025-04-20T21:23:59.433+0800] {processor.py:914} INFO - Processing file /mnt/c/Users/wu_li/OneDrive/Desktop/Airflow_pract/dags/first_dag.py for tasks to queue
[2025-04-20T21:23:59.436+0800] {logging_mixin.py:190} INFO - [2025-04-20T21:23:59.435+0800] {dagbag.py:588} INFO - Filling up the DagBag from /mnt/c/Users/wu_li/OneDrive/Desktop/Airflow_pract/dags/first_dag.py
[2025-04-20T21:23:59.460+0800] {logging_mixin.py:190} INFO - [2025-04-20T21:23:59.451+0800] {dagbag.py:387} ERROR - Failed to import: /mnt/c/Users/wu_li/OneDrive/Desktop/Airflow_pract/dags/first_dag.py
Traceback (most recent call last):
  File "/mnt/c/Users/wu_li/OneDrive/Desktop/Airflow_pract/venv/lib/python3.9/site-packages/airflow/models/dagbag.py", line 383, in parse
    loader.exec_module(new_module)
  File "<frozen importlib._bootstrap_external>", line 850, in exec_module
  File "<frozen importlib._bootstrap>", line 228, in _call_with_frames_removed
  File "/mnt/c/Users/wu_li/OneDrive/Desktop/Airflow_pract/dags/first_dag.py", line 2, in <module>
    from airflow import first_dag
ImportError: cannot import name 'first_dag' from 'airflow' (/mnt/c/Users/wu_li/OneDrive/Desktop/Airflow_pract/venv/lib/python3.9/site-packages/airflow/__init__.py)
[2025-04-20T21:23:59.462+0800] {processor.py:927} WARNING - No viable dags retrieved from /mnt/c/Users/wu_li/OneDrive/Desktop/Airflow_pract/dags/first_dag.py
[2025-04-20T21:23:59.501+0800] {processor.py:208} INFO - Processing /mnt/c/Users/wu_li/OneDrive/Desktop/Airflow_pract/dags/first_dag.py took 0.083 seconds
[2025-04-20T21:24:44.433+0800] {processor.py:186} INFO - Started process (PID=108002) to work on /mnt/c/Users/wu_li/OneDrive/Desktop/Airflow_pract/dags/first_dag.py
[2025-04-20T21:24:44.434+0800] {processor.py:914} INFO - Processing file /mnt/c/Users/wu_li/OneDrive/Desktop/Airflow_pract/dags/first_dag.py for tasks to queue
[2025-04-20T21:24:44.436+0800] {logging_mixin.py:190} INFO - [2025-04-20T21:24:44.436+0800] {dagbag.py:588} INFO - Filling up the DagBag from /mnt/c/Users/wu_li/OneDrive/Desktop/Airflow_pract/dags/first_dag.py
[2025-04-20T21:24:44.459+0800] {logging_mixin.py:190} INFO - [2025-04-20T21:24:44.451+0800] {dagbag.py:387} ERROR - Failed to import: /mnt/c/Users/wu_li/OneDrive/Desktop/Airflow_pract/dags/first_dag.py
Traceback (most recent call last):
  File "/mnt/c/Users/wu_li/OneDrive/Desktop/Airflow_pract/venv/lib/python3.9/site-packages/airflow/models/dagbag.py", line 383, in parse
    loader.exec_module(new_module)
  File "<frozen importlib._bootstrap_external>", line 850, in exec_module
  File "<frozen importlib._bootstrap>", line 228, in _call_with_frames_removed
  File "/mnt/c/Users/wu_li/OneDrive/Desktop/Airflow_pract/dags/first_dag.py", line 2, in <module>
    from airflow import first_dag
ImportError: cannot import name 'first_dag' from 'airflow' (/mnt/c/Users/wu_li/OneDrive/Desktop/Airflow_pract/venv/lib/python3.9/site-packages/airflow/__init__.py)
[2025-04-20T21:24:44.461+0800] {processor.py:927} WARNING - No viable dags retrieved from /mnt/c/Users/wu_li/OneDrive/Desktop/Airflow_pract/dags/first_dag.py
[2025-04-20T21:24:44.502+0800] {processor.py:208} INFO - Processing /mnt/c/Users/wu_li/OneDrive/Desktop/Airflow_pract/dags/first_dag.py took 0.079 seconds
[2025-04-20T21:25:29.356+0800] {processor.py:186} INFO - Started process (PID=108539) to work on /mnt/c/Users/wu_li/OneDrive/Desktop/Airflow_pract/dags/first_dag.py
[2025-04-20T21:25:29.362+0800] {processor.py:914} INFO - Processing file /mnt/c/Users/wu_li/OneDrive/Desktop/Airflow_pract/dags/first_dag.py for tasks to queue
[2025-04-20T21:25:29.368+0800] {logging_mixin.py:190} INFO - [2025-04-20T21:25:29.367+0800] {dagbag.py:588} INFO - Filling up the DagBag from /mnt/c/Users/wu_li/OneDrive/Desktop/Airflow_pract/dags/first_dag.py
[2025-04-20T21:25:29.441+0800] {logging_mixin.py:190} INFO - [2025-04-20T21:25:29.421+0800] {dagbag.py:387} ERROR - Failed to import: /mnt/c/Users/wu_li/OneDrive/Desktop/Airflow_pract/dags/first_dag.py
Traceback (most recent call last):
  File "/mnt/c/Users/wu_li/OneDrive/Desktop/Airflow_pract/venv/lib/python3.9/site-packages/airflow/models/dagbag.py", line 383, in parse
    loader.exec_module(new_module)
  File "<frozen importlib._bootstrap_external>", line 850, in exec_module
  File "<frozen importlib._bootstrap>", line 228, in _call_with_frames_removed
  File "/mnt/c/Users/wu_li/OneDrive/Desktop/Airflow_pract/dags/first_dag.py", line 2, in <module>
    from airflow import first_dag
ImportError: cannot import name 'first_dag' from 'airflow' (/mnt/c/Users/wu_li/OneDrive/Desktop/Airflow_pract/venv/lib/python3.9/site-packages/airflow/__init__.py)
[2025-04-20T21:25:29.445+0800] {processor.py:927} WARNING - No viable dags retrieved from /mnt/c/Users/wu_li/OneDrive/Desktop/Airflow_pract/dags/first_dag.py
[2025-04-20T21:25:29.501+0800] {processor.py:208} INFO - Processing /mnt/c/Users/wu_li/OneDrive/Desktop/Airflow_pract/dags/first_dag.py took 0.164 seconds
[2025-04-20T21:26:16.081+0800] {processor.py:186} INFO - Started process (PID=109078) to work on /mnt/c/Users/wu_li/OneDrive/Desktop/Airflow_pract/dags/first_dag.py
[2025-04-20T21:26:16.083+0800] {processor.py:914} INFO - Processing file /mnt/c/Users/wu_li/OneDrive/Desktop/Airflow_pract/dags/first_dag.py for tasks to queue
[2025-04-20T21:26:16.090+0800] {logging_mixin.py:190} INFO - [2025-04-20T21:26:16.088+0800] {dagbag.py:588} INFO - Filling up the DagBag from /mnt/c/Users/wu_li/OneDrive/Desktop/Airflow_pract/dags/first_dag.py
[2025-04-20T21:26:16.124+0800] {logging_mixin.py:190} INFO - [2025-04-20T21:26:16.112+0800] {dagbag.py:387} ERROR - Failed to import: /mnt/c/Users/wu_li/OneDrive/Desktop/Airflow_pract/dags/first_dag.py
Traceback (most recent call last):
  File "/mnt/c/Users/wu_li/OneDrive/Desktop/Airflow_pract/venv/lib/python3.9/site-packages/airflow/models/dagbag.py", line 383, in parse
    loader.exec_module(new_module)
  File "<frozen importlib._bootstrap_external>", line 850, in exec_module
  File "<frozen importlib._bootstrap>", line 228, in _call_with_frames_removed
  File "/mnt/c/Users/wu_li/OneDrive/Desktop/Airflow_pract/dags/first_dag.py", line 2, in <module>
    from airflow import first_dag
ImportError: cannot import name 'first_dag' from 'airflow' (/mnt/c/Users/wu_li/OneDrive/Desktop/Airflow_pract/venv/lib/python3.9/site-packages/airflow/__init__.py)
[2025-04-20T21:26:16.128+0800] {processor.py:927} WARNING - No viable dags retrieved from /mnt/c/Users/wu_li/OneDrive/Desktop/Airflow_pract/dags/first_dag.py
[2025-04-20T21:26:16.189+0800] {processor.py:208} INFO - Processing /mnt/c/Users/wu_li/OneDrive/Desktop/Airflow_pract/dags/first_dag.py took 0.127 seconds
[2025-04-20T21:27:00.922+0800] {processor.py:186} INFO - Started process (PID=109548) to work on /mnt/c/Users/wu_li/OneDrive/Desktop/Airflow_pract/dags/first_dag.py
[2025-04-20T21:27:00.924+0800] {processor.py:914} INFO - Processing file /mnt/c/Users/wu_li/OneDrive/Desktop/Airflow_pract/dags/first_dag.py for tasks to queue
[2025-04-20T21:27:00.927+0800] {logging_mixin.py:190} INFO - [2025-04-20T21:27:00.926+0800] {dagbag.py:588} INFO - Filling up the DagBag from /mnt/c/Users/wu_li/OneDrive/Desktop/Airflow_pract/dags/first_dag.py
[2025-04-20T21:27:00.959+0800] {logging_mixin.py:190} INFO - [2025-04-20T21:27:00.948+0800] {dagbag.py:387} ERROR - Failed to import: /mnt/c/Users/wu_li/OneDrive/Desktop/Airflow_pract/dags/first_dag.py
Traceback (most recent call last):
  File "/mnt/c/Users/wu_li/OneDrive/Desktop/Airflow_pract/venv/lib/python3.9/site-packages/airflow/models/dagbag.py", line 383, in parse
    loader.exec_module(new_module)
  File "<frozen importlib._bootstrap_external>", line 850, in exec_module
  File "<frozen importlib._bootstrap>", line 228, in _call_with_frames_removed
  File "/mnt/c/Users/wu_li/OneDrive/Desktop/Airflow_pract/dags/first_dag.py", line 2, in <module>
    from airflow import first_dag
ImportError: cannot import name 'first_dag' from 'airflow' (/mnt/c/Users/wu_li/OneDrive/Desktop/Airflow_pract/venv/lib/python3.9/site-packages/airflow/__init__.py)
[2025-04-20T21:27:00.961+0800] {processor.py:927} WARNING - No viable dags retrieved from /mnt/c/Users/wu_li/OneDrive/Desktop/Airflow_pract/dags/first_dag.py
[2025-04-20T21:27:01.002+0800] {processor.py:208} INFO - Processing /mnt/c/Users/wu_li/OneDrive/Desktop/Airflow_pract/dags/first_dag.py took 0.091 seconds
[2025-04-20T21:27:44.509+0800] {processor.py:186} INFO - Started process (PID=110085) to work on /mnt/c/Users/wu_li/OneDrive/Desktop/Airflow_pract/dags/first_dag.py
[2025-04-20T21:27:44.512+0800] {processor.py:914} INFO - Processing file /mnt/c/Users/wu_li/OneDrive/Desktop/Airflow_pract/dags/first_dag.py for tasks to queue
[2025-04-20T21:27:44.517+0800] {logging_mixin.py:190} INFO - [2025-04-20T21:27:44.514+0800] {dagbag.py:588} INFO - Filling up the DagBag from /mnt/c/Users/wu_li/OneDrive/Desktop/Airflow_pract/dags/first_dag.py
[2025-04-20T21:27:44.570+0800] {logging_mixin.py:190} INFO - [2025-04-20T21:27:44.553+0800] {dagbag.py:387} ERROR - Failed to import: /mnt/c/Users/wu_li/OneDrive/Desktop/Airflow_pract/dags/first_dag.py
Traceback (most recent call last):
  File "/mnt/c/Users/wu_li/OneDrive/Desktop/Airflow_pract/venv/lib/python3.9/site-packages/airflow/models/dagbag.py", line 383, in parse
    loader.exec_module(new_module)
  File "<frozen importlib._bootstrap_external>", line 850, in exec_module
  File "<frozen importlib._bootstrap>", line 228, in _call_with_frames_removed
  File "/mnt/c/Users/wu_li/OneDrive/Desktop/Airflow_pract/dags/first_dag.py", line 2, in <module>
    from airflow import first_dag
ImportError: cannot import name 'first_dag' from 'airflow' (/mnt/c/Users/wu_li/OneDrive/Desktop/Airflow_pract/venv/lib/python3.9/site-packages/airflow/__init__.py)
[2025-04-20T21:27:44.573+0800] {processor.py:927} WARNING - No viable dags retrieved from /mnt/c/Users/wu_li/OneDrive/Desktop/Airflow_pract/dags/first_dag.py
[2025-04-20T21:27:44.628+0800] {processor.py:208} INFO - Processing /mnt/c/Users/wu_li/OneDrive/Desktop/Airflow_pract/dags/first_dag.py took 0.138 seconds
[2025-04-20T21:28:30.914+0800] {processor.py:186} INFO - Started process (PID=110626) to work on /mnt/c/Users/wu_li/OneDrive/Desktop/Airflow_pract/dags/first_dag.py
[2025-04-20T21:28:30.920+0800] {processor.py:914} INFO - Processing file /mnt/c/Users/wu_li/OneDrive/Desktop/Airflow_pract/dags/first_dag.py for tasks to queue
[2025-04-20T21:28:30.932+0800] {logging_mixin.py:190} INFO - [2025-04-20T21:28:30.930+0800] {dagbag.py:588} INFO - Filling up the DagBag from /mnt/c/Users/wu_li/OneDrive/Desktop/Airflow_pract/dags/first_dag.py
[2025-04-20T21:28:30.976+0800] {logging_mixin.py:190} INFO - [2025-04-20T21:28:30.963+0800] {dagbag.py:387} ERROR - Failed to import: /mnt/c/Users/wu_li/OneDrive/Desktop/Airflow_pract/dags/first_dag.py
Traceback (most recent call last):
  File "/mnt/c/Users/wu_li/OneDrive/Desktop/Airflow_pract/venv/lib/python3.9/site-packages/airflow/models/dagbag.py", line 383, in parse
    loader.exec_module(new_module)
  File "<frozen importlib._bootstrap_external>", line 850, in exec_module
  File "<frozen importlib._bootstrap>", line 228, in _call_with_frames_removed
  File "/mnt/c/Users/wu_li/OneDrive/Desktop/Airflow_pract/dags/first_dag.py", line 2, in <module>
    from airflow import first_dag
ImportError: cannot import name 'first_dag' from 'airflow' (/mnt/c/Users/wu_li/OneDrive/Desktop/Airflow_pract/venv/lib/python3.9/site-packages/airflow/__init__.py)
[2025-04-20T21:28:30.986+0800] {processor.py:927} WARNING - No viable dags retrieved from /mnt/c/Users/wu_li/OneDrive/Desktop/Airflow_pract/dags/first_dag.py
[2025-04-20T21:28:31.062+0800] {processor.py:208} INFO - Processing /mnt/c/Users/wu_li/OneDrive/Desktop/Airflow_pract/dags/first_dag.py took 0.173 seconds
[2025-04-20T21:29:18.386+0800] {processor.py:186} INFO - Started process (PID=111170) to work on /mnt/c/Users/wu_li/OneDrive/Desktop/Airflow_pract/dags/first_dag.py
[2025-04-20T21:29:18.388+0800] {processor.py:914} INFO - Processing file /mnt/c/Users/wu_li/OneDrive/Desktop/Airflow_pract/dags/first_dag.py for tasks to queue
[2025-04-20T21:29:18.391+0800] {logging_mixin.py:190} INFO - [2025-04-20T21:29:18.390+0800] {dagbag.py:588} INFO - Filling up the DagBag from /mnt/c/Users/wu_li/OneDrive/Desktop/Airflow_pract/dags/first_dag.py
[2025-04-20T21:29:18.418+0800] {logging_mixin.py:190} INFO - [2025-04-20T21:29:18.408+0800] {dagbag.py:387} ERROR - Failed to import: /mnt/c/Users/wu_li/OneDrive/Desktop/Airflow_pract/dags/first_dag.py
Traceback (most recent call last):
  File "/mnt/c/Users/wu_li/OneDrive/Desktop/Airflow_pract/venv/lib/python3.9/site-packages/airflow/models/dagbag.py", line 383, in parse
    loader.exec_module(new_module)
  File "<frozen importlib._bootstrap_external>", line 850, in exec_module
  File "<frozen importlib._bootstrap>", line 228, in _call_with_frames_removed
  File "/mnt/c/Users/wu_li/OneDrive/Desktop/Airflow_pract/dags/first_dag.py", line 2, in <module>
    from airflow import first_dag
ImportError: cannot import name 'first_dag' from 'airflow' (/mnt/c/Users/wu_li/OneDrive/Desktop/Airflow_pract/venv/lib/python3.9/site-packages/airflow/__init__.py)
[2025-04-20T21:29:18.421+0800] {processor.py:927} WARNING - No viable dags retrieved from /mnt/c/Users/wu_li/OneDrive/Desktop/Airflow_pract/dags/first_dag.py
[2025-04-20T21:29:18.454+0800] {processor.py:208} INFO - Processing /mnt/c/Users/wu_li/OneDrive/Desktop/Airflow_pract/dags/first_dag.py took 0.080 seconds
[2025-04-20T21:30:02.421+0800] {processor.py:186} INFO - Started process (PID=111708) to work on /mnt/c/Users/wu_li/OneDrive/Desktop/Airflow_pract/dags/first_dag.py
[2025-04-20T21:30:02.423+0800] {processor.py:914} INFO - Processing file /mnt/c/Users/wu_li/OneDrive/Desktop/Airflow_pract/dags/first_dag.py for tasks to queue
[2025-04-20T21:30:02.427+0800] {logging_mixin.py:190} INFO - [2025-04-20T21:30:02.425+0800] {dagbag.py:588} INFO - Filling up the DagBag from /mnt/c/Users/wu_li/OneDrive/Desktop/Airflow_pract/dags/first_dag.py
[2025-04-20T21:30:02.460+0800] {logging_mixin.py:190} INFO - [2025-04-20T21:30:02.448+0800] {dagbag.py:387} ERROR - Failed to import: /mnt/c/Users/wu_li/OneDrive/Desktop/Airflow_pract/dags/first_dag.py
Traceback (most recent call last):
  File "/mnt/c/Users/wu_li/OneDrive/Desktop/Airflow_pract/venv/lib/python3.9/site-packages/airflow/models/dagbag.py", line 383, in parse
    loader.exec_module(new_module)
  File "<frozen importlib._bootstrap_external>", line 850, in exec_module
  File "<frozen importlib._bootstrap>", line 228, in _call_with_frames_removed
  File "/mnt/c/Users/wu_li/OneDrive/Desktop/Airflow_pract/dags/first_dag.py", line 2, in <module>
    from airflow import first_dag
ImportError: cannot import name 'first_dag' from 'airflow' (/mnt/c/Users/wu_li/OneDrive/Desktop/Airflow_pract/venv/lib/python3.9/site-packages/airflow/__init__.py)
[2025-04-20T21:30:02.463+0800] {processor.py:927} WARNING - No viable dags retrieved from /mnt/c/Users/wu_li/OneDrive/Desktop/Airflow_pract/dags/first_dag.py
[2025-04-20T21:30:02.524+0800] {processor.py:208} INFO - Processing /mnt/c/Users/wu_li/OneDrive/Desktop/Airflow_pract/dags/first_dag.py took 0.122 seconds
[2025-04-20T21:30:48.383+0800] {processor.py:186} INFO - Started process (PID=112246) to work on /mnt/c/Users/wu_li/OneDrive/Desktop/Airflow_pract/dags/first_dag.py
[2025-04-20T21:30:48.386+0800] {processor.py:914} INFO - Processing file /mnt/c/Users/wu_li/OneDrive/Desktop/Airflow_pract/dags/first_dag.py for tasks to queue
[2025-04-20T21:30:48.389+0800] {logging_mixin.py:190} INFO - [2025-04-20T21:30:48.388+0800] {dagbag.py:588} INFO - Filling up the DagBag from /mnt/c/Users/wu_li/OneDrive/Desktop/Airflow_pract/dags/first_dag.py
[2025-04-20T21:30:48.428+0800] {logging_mixin.py:190} INFO - [2025-04-20T21:30:48.415+0800] {dagbag.py:387} ERROR - Failed to import: /mnt/c/Users/wu_li/OneDrive/Desktop/Airflow_pract/dags/first_dag.py
Traceback (most recent call last):
  File "/mnt/c/Users/wu_li/OneDrive/Desktop/Airflow_pract/venv/lib/python3.9/site-packages/airflow/models/dagbag.py", line 383, in parse
    loader.exec_module(new_module)
  File "<frozen importlib._bootstrap_external>", line 850, in exec_module
  File "<frozen importlib._bootstrap>", line 228, in _call_with_frames_removed
  File "/mnt/c/Users/wu_li/OneDrive/Desktop/Airflow_pract/dags/first_dag.py", line 2, in <module>
    from airflow import first_dag
ImportError: cannot import name 'first_dag' from 'airflow' (/mnt/c/Users/wu_li/OneDrive/Desktop/Airflow_pract/venv/lib/python3.9/site-packages/airflow/__init__.py)
[2025-04-20T21:30:48.431+0800] {processor.py:927} WARNING - No viable dags retrieved from /mnt/c/Users/wu_li/OneDrive/Desktop/Airflow_pract/dags/first_dag.py
[2025-04-20T21:30:48.497+0800] {processor.py:208} INFO - Processing /mnt/c/Users/wu_li/OneDrive/Desktop/Airflow_pract/dags/first_dag.py took 0.133 seconds
[2025-04-20T21:31:34.388+0800] {processor.py:186} INFO - Started process (PID=112751) to work on /mnt/c/Users/wu_li/OneDrive/Desktop/Airflow_pract/dags/first_dag.py
[2025-04-20T21:31:34.389+0800] {processor.py:914} INFO - Processing file /mnt/c/Users/wu_li/OneDrive/Desktop/Airflow_pract/dags/first_dag.py for tasks to queue
[2025-04-20T21:31:34.392+0800] {logging_mixin.py:190} INFO - [2025-04-20T21:31:34.391+0800] {dagbag.py:588} INFO - Filling up the DagBag from /mnt/c/Users/wu_li/OneDrive/Desktop/Airflow_pract/dags/first_dag.py
[2025-04-20T21:31:34.414+0800] {logging_mixin.py:190} INFO - [2025-04-20T21:31:34.406+0800] {dagbag.py:387} ERROR - Failed to import: /mnt/c/Users/wu_li/OneDrive/Desktop/Airflow_pract/dags/first_dag.py
Traceback (most recent call last):
  File "/mnt/c/Users/wu_li/OneDrive/Desktop/Airflow_pract/venv/lib/python3.9/site-packages/airflow/models/dagbag.py", line 383, in parse
    loader.exec_module(new_module)
  File "<frozen importlib._bootstrap_external>", line 850, in exec_module
  File "<frozen importlib._bootstrap>", line 228, in _call_with_frames_removed
  File "/mnt/c/Users/wu_li/OneDrive/Desktop/Airflow_pract/dags/first_dag.py", line 2, in <module>
    from airflow import first_dag
ImportError: cannot import name 'first_dag' from 'airflow' (/mnt/c/Users/wu_li/OneDrive/Desktop/Airflow_pract/venv/lib/python3.9/site-packages/airflow/__init__.py)
[2025-04-20T21:31:34.417+0800] {processor.py:927} WARNING - No viable dags retrieved from /mnt/c/Users/wu_li/OneDrive/Desktop/Airflow_pract/dags/first_dag.py
[2025-04-20T21:31:34.454+0800] {processor.py:208} INFO - Processing /mnt/c/Users/wu_li/OneDrive/Desktop/Airflow_pract/dags/first_dag.py took 0.087 seconds
[2025-04-20T21:32:21.270+0800] {processor.py:186} INFO - Started process (PID=113259) to work on /mnt/c/Users/wu_li/OneDrive/Desktop/Airflow_pract/dags/first_dag.py
[2025-04-20T21:32:21.272+0800] {processor.py:914} INFO - Processing file /mnt/c/Users/wu_li/OneDrive/Desktop/Airflow_pract/dags/first_dag.py for tasks to queue
[2025-04-20T21:32:21.274+0800] {logging_mixin.py:190} INFO - [2025-04-20T21:32:21.273+0800] {dagbag.py:588} INFO - Filling up the DagBag from /mnt/c/Users/wu_li/OneDrive/Desktop/Airflow_pract/dags/first_dag.py
[2025-04-20T21:32:21.297+0800] {logging_mixin.py:190} INFO - [2025-04-20T21:32:21.289+0800] {dagbag.py:387} ERROR - Failed to import: /mnt/c/Users/wu_li/OneDrive/Desktop/Airflow_pract/dags/first_dag.py
Traceback (most recent call last):
  File "/mnt/c/Users/wu_li/OneDrive/Desktop/Airflow_pract/venv/lib/python3.9/site-packages/airflow/models/dagbag.py", line 383, in parse
    loader.exec_module(new_module)
  File "<frozen importlib._bootstrap_external>", line 850, in exec_module
  File "<frozen importlib._bootstrap>", line 228, in _call_with_frames_removed
  File "/mnt/c/Users/wu_li/OneDrive/Desktop/Airflow_pract/dags/first_dag.py", line 2, in <module>
    from airflow import first_dag
ImportError: cannot import name 'first_dag' from 'airflow' (/mnt/c/Users/wu_li/OneDrive/Desktop/Airflow_pract/venv/lib/python3.9/site-packages/airflow/__init__.py)
[2025-04-20T21:32:21.299+0800] {processor.py:927} WARNING - No viable dags retrieved from /mnt/c/Users/wu_li/OneDrive/Desktop/Airflow_pract/dags/first_dag.py
[2025-04-20T21:32:21.345+0800] {processor.py:208} INFO - Processing /mnt/c/Users/wu_li/OneDrive/Desktop/Airflow_pract/dags/first_dag.py took 0.088 seconds
[2025-04-20T21:33:05.343+0800] {processor.py:186} INFO - Started process (PID=113798) to work on /mnt/c/Users/wu_li/OneDrive/Desktop/Airflow_pract/dags/first_dag.py
[2025-04-20T21:33:05.345+0800] {processor.py:914} INFO - Processing file /mnt/c/Users/wu_li/OneDrive/Desktop/Airflow_pract/dags/first_dag.py for tasks to queue
[2025-04-20T21:33:05.347+0800] {logging_mixin.py:190} INFO - [2025-04-20T21:33:05.346+0800] {dagbag.py:588} INFO - Filling up the DagBag from /mnt/c/Users/wu_li/OneDrive/Desktop/Airflow_pract/dags/first_dag.py
[2025-04-20T21:33:05.374+0800] {logging_mixin.py:190} INFO - [2025-04-20T21:33:05.364+0800] {dagbag.py:387} ERROR - Failed to import: /mnt/c/Users/wu_li/OneDrive/Desktop/Airflow_pract/dags/first_dag.py
Traceback (most recent call last):
  File "/mnt/c/Users/wu_li/OneDrive/Desktop/Airflow_pract/venv/lib/python3.9/site-packages/airflow/models/dagbag.py", line 383, in parse
    loader.exec_module(new_module)
  File "<frozen importlib._bootstrap_external>", line 850, in exec_module
  File "<frozen importlib._bootstrap>", line 228, in _call_with_frames_removed
  File "/mnt/c/Users/wu_li/OneDrive/Desktop/Airflow_pract/dags/first_dag.py", line 2, in <module>
    from airflow import first_dag
ImportError: cannot import name 'first_dag' from 'airflow' (/mnt/c/Users/wu_li/OneDrive/Desktop/Airflow_pract/venv/lib/python3.9/site-packages/airflow/__init__.py)
[2025-04-20T21:33:05.377+0800] {processor.py:927} WARNING - No viable dags retrieved from /mnt/c/Users/wu_li/OneDrive/Desktop/Airflow_pract/dags/first_dag.py
[2025-04-20T21:33:05.416+0800] {processor.py:208} INFO - Processing /mnt/c/Users/wu_li/OneDrive/Desktop/Airflow_pract/dags/first_dag.py took 0.085 seconds
[2025-04-20T21:33:49.141+0800] {processor.py:186} INFO - Started process (PID=114334) to work on /mnt/c/Users/wu_li/OneDrive/Desktop/Airflow_pract/dags/first_dag.py
[2025-04-20T21:33:49.144+0800] {processor.py:914} INFO - Processing file /mnt/c/Users/wu_li/OneDrive/Desktop/Airflow_pract/dags/first_dag.py for tasks to queue
[2025-04-20T21:33:49.149+0800] {logging_mixin.py:190} INFO - [2025-04-20T21:33:49.147+0800] {dagbag.py:588} INFO - Filling up the DagBag from /mnt/c/Users/wu_li/OneDrive/Desktop/Airflow_pract/dags/first_dag.py
[2025-04-20T21:33:49.185+0800] {logging_mixin.py:190} INFO - [2025-04-20T21:33:49.172+0800] {dagbag.py:387} ERROR - Failed to import: /mnt/c/Users/wu_li/OneDrive/Desktop/Airflow_pract/dags/first_dag.py
Traceback (most recent call last):
  File "/mnt/c/Users/wu_li/OneDrive/Desktop/Airflow_pract/venv/lib/python3.9/site-packages/airflow/models/dagbag.py", line 383, in parse
    loader.exec_module(new_module)
  File "<frozen importlib._bootstrap_external>", line 850, in exec_module
  File "<frozen importlib._bootstrap>", line 228, in _call_with_frames_removed
  File "/mnt/c/Users/wu_li/OneDrive/Desktop/Airflow_pract/dags/first_dag.py", line 2, in <module>
    from airflow import first_dag
ImportError: cannot import name 'first_dag' from 'airflow' (/mnt/c/Users/wu_li/OneDrive/Desktop/Airflow_pract/venv/lib/python3.9/site-packages/airflow/__init__.py)
[2025-04-20T21:33:49.189+0800] {processor.py:927} WARNING - No viable dags retrieved from /mnt/c/Users/wu_li/OneDrive/Desktop/Airflow_pract/dags/first_dag.py
[2025-04-20T21:33:49.252+0800] {processor.py:208} INFO - Processing /mnt/c/Users/wu_li/OneDrive/Desktop/Airflow_pract/dags/first_dag.py took 0.140 seconds
[2025-04-20T21:34:36.062+0800] {processor.py:186} INFO - Started process (PID=114874) to work on /mnt/c/Users/wu_li/OneDrive/Desktop/Airflow_pract/dags/first_dag.py
[2025-04-20T21:34:36.065+0800] {processor.py:914} INFO - Processing file /mnt/c/Users/wu_li/OneDrive/Desktop/Airflow_pract/dags/first_dag.py for tasks to queue
[2025-04-20T21:34:36.069+0800] {logging_mixin.py:190} INFO - [2025-04-20T21:34:36.067+0800] {dagbag.py:588} INFO - Filling up the DagBag from /mnt/c/Users/wu_li/OneDrive/Desktop/Airflow_pract/dags/first_dag.py
[2025-04-20T21:34:36.101+0800] {logging_mixin.py:190} INFO - [2025-04-20T21:34:36.089+0800] {dagbag.py:387} ERROR - Failed to import: /mnt/c/Users/wu_li/OneDrive/Desktop/Airflow_pract/dags/first_dag.py
Traceback (most recent call last):
  File "/mnt/c/Users/wu_li/OneDrive/Desktop/Airflow_pract/venv/lib/python3.9/site-packages/airflow/models/dagbag.py", line 383, in parse
    loader.exec_module(new_module)
  File "<frozen importlib._bootstrap_external>", line 850, in exec_module
  File "<frozen importlib._bootstrap>", line 228, in _call_with_frames_removed
  File "/mnt/c/Users/wu_li/OneDrive/Desktop/Airflow_pract/dags/first_dag.py", line 2, in <module>
    from airflow import first_dag
ImportError: cannot import name 'first_dag' from 'airflow' (/mnt/c/Users/wu_li/OneDrive/Desktop/Airflow_pract/venv/lib/python3.9/site-packages/airflow/__init__.py)
[2025-04-20T21:34:36.104+0800] {processor.py:927} WARNING - No viable dags retrieved from /mnt/c/Users/wu_li/OneDrive/Desktop/Airflow_pract/dags/first_dag.py
[2025-04-20T21:34:36.158+0800] {processor.py:208} INFO - Processing /mnt/c/Users/wu_li/OneDrive/Desktop/Airflow_pract/dags/first_dag.py took 0.116 seconds
[2025-04-20T21:35:26.583+0800] {processor.py:186} INFO - Started process (PID=115486) to work on /mnt/c/Users/wu_li/OneDrive/Desktop/Airflow_pract/dags/first_dag.py
[2025-04-20T21:35:26.585+0800] {processor.py:914} INFO - Processing file /mnt/c/Users/wu_li/OneDrive/Desktop/Airflow_pract/dags/first_dag.py for tasks to queue
[2025-04-20T21:35:26.587+0800] {logging_mixin.py:190} INFO - [2025-04-20T21:35:26.586+0800] {dagbag.py:588} INFO - Filling up the DagBag from /mnt/c/Users/wu_li/OneDrive/Desktop/Airflow_pract/dags/first_dag.py
[2025-04-20T21:35:26.628+0800] {logging_mixin.py:190} INFO - [2025-04-20T21:35:26.611+0800] {dagbag.py:387} ERROR - Failed to import: /mnt/c/Users/wu_li/OneDrive/Desktop/Airflow_pract/dags/first_dag.py
Traceback (most recent call last):
  File "/mnt/c/Users/wu_li/OneDrive/Desktop/Airflow_pract/venv/lib/python3.9/site-packages/airflow/models/dagbag.py", line 383, in parse
    loader.exec_module(new_module)
  File "<frozen importlib._bootstrap_external>", line 850, in exec_module
  File "<frozen importlib._bootstrap>", line 228, in _call_with_frames_removed
  File "/mnt/c/Users/wu_li/OneDrive/Desktop/Airflow_pract/dags/first_dag.py", line 2, in <module>
    from airflow import first_dag
ImportError: cannot import name 'first_dag' from 'airflow' (/mnt/c/Users/wu_li/OneDrive/Desktop/Airflow_pract/venv/lib/python3.9/site-packages/airflow/__init__.py)
[2025-04-20T21:35:26.631+0800] {processor.py:927} WARNING - No viable dags retrieved from /mnt/c/Users/wu_li/OneDrive/Desktop/Airflow_pract/dags/first_dag.py
[2025-04-20T21:35:26.700+0800] {processor.py:208} INFO - Processing /mnt/c/Users/wu_li/OneDrive/Desktop/Airflow_pract/dags/first_dag.py took 0.129 seconds
[2025-04-20T21:36:15.414+0800] {processor.py:186} INFO - Started process (PID=116029) to work on /mnt/c/Users/wu_li/OneDrive/Desktop/Airflow_pract/dags/first_dag.py
[2025-04-20T21:36:15.415+0800] {processor.py:914} INFO - Processing file /mnt/c/Users/wu_li/OneDrive/Desktop/Airflow_pract/dags/first_dag.py for tasks to queue
[2025-04-20T21:36:15.418+0800] {logging_mixin.py:190} INFO - [2025-04-20T21:36:15.417+0800] {dagbag.py:588} INFO - Filling up the DagBag from /mnt/c/Users/wu_li/OneDrive/Desktop/Airflow_pract/dags/first_dag.py
[2025-04-20T21:36:15.441+0800] {logging_mixin.py:190} INFO - [2025-04-20T21:36:15.432+0800] {dagbag.py:387} ERROR - Failed to import: /mnt/c/Users/wu_li/OneDrive/Desktop/Airflow_pract/dags/first_dag.py
Traceback (most recent call last):
  File "/mnt/c/Users/wu_li/OneDrive/Desktop/Airflow_pract/venv/lib/python3.9/site-packages/airflow/models/dagbag.py", line 383, in parse
    loader.exec_module(new_module)
  File "<frozen importlib._bootstrap_external>", line 850, in exec_module
  File "<frozen importlib._bootstrap>", line 228, in _call_with_frames_removed
  File "/mnt/c/Users/wu_li/OneDrive/Desktop/Airflow_pract/dags/first_dag.py", line 2, in <module>
    from airflow import first_dag
ImportError: cannot import name 'first_dag' from 'airflow' (/mnt/c/Users/wu_li/OneDrive/Desktop/Airflow_pract/venv/lib/python3.9/site-packages/airflow/__init__.py)
[2025-04-20T21:36:15.444+0800] {processor.py:927} WARNING - No viable dags retrieved from /mnt/c/Users/wu_li/OneDrive/Desktop/Airflow_pract/dags/first_dag.py
[2025-04-20T21:36:15.484+0800] {processor.py:208} INFO - Processing /mnt/c/Users/wu_li/OneDrive/Desktop/Airflow_pract/dags/first_dag.py took 0.082 seconds
[2025-04-20T21:37:05.234+0800] {processor.py:186} INFO - Started process (PID=116641) to work on /mnt/c/Users/wu_li/OneDrive/Desktop/Airflow_pract/dags/first_dag.py
[2025-04-20T21:37:05.236+0800] {processor.py:914} INFO - Processing file /mnt/c/Users/wu_li/OneDrive/Desktop/Airflow_pract/dags/first_dag.py for tasks to queue
[2025-04-20T21:37:05.240+0800] {logging_mixin.py:190} INFO - [2025-04-20T21:37:05.239+0800] {dagbag.py:588} INFO - Filling up the DagBag from /mnt/c/Users/wu_li/OneDrive/Desktop/Airflow_pract/dags/first_dag.py
[2025-04-20T21:37:05.274+0800] {logging_mixin.py:190} INFO - [2025-04-20T21:37:05.262+0800] {dagbag.py:387} ERROR - Failed to import: /mnt/c/Users/wu_li/OneDrive/Desktop/Airflow_pract/dags/first_dag.py
Traceback (most recent call last):
  File "/mnt/c/Users/wu_li/OneDrive/Desktop/Airflow_pract/venv/lib/python3.9/site-packages/airflow/models/dagbag.py", line 383, in parse
    loader.exec_module(new_module)
  File "<frozen importlib._bootstrap_external>", line 850, in exec_module
  File "<frozen importlib._bootstrap>", line 228, in _call_with_frames_removed
  File "/mnt/c/Users/wu_li/OneDrive/Desktop/Airflow_pract/dags/first_dag.py", line 2, in <module>
    from airflow import first_dag
ImportError: cannot import name 'first_dag' from 'airflow' (/mnt/c/Users/wu_li/OneDrive/Desktop/Airflow_pract/venv/lib/python3.9/site-packages/airflow/__init__.py)
[2025-04-20T21:37:05.277+0800] {processor.py:927} WARNING - No viable dags retrieved from /mnt/c/Users/wu_li/OneDrive/Desktop/Airflow_pract/dags/first_dag.py
[2025-04-20T21:37:05.346+0800] {processor.py:208} INFO - Processing /mnt/c/Users/wu_li/OneDrive/Desktop/Airflow_pract/dags/first_dag.py took 0.130 seconds
[2025-04-20T21:38:00.370+0800] {processor.py:186} INFO - Started process (PID=117009) to work on /mnt/c/Users/wu_li/OneDrive/Desktop/Airflow_pract/dags/first_dag.py
[2025-04-20T21:38:00.371+0800] {processor.py:914} INFO - Processing file /mnt/c/Users/wu_li/OneDrive/Desktop/Airflow_pract/dags/first_dag.py for tasks to queue
[2025-04-20T21:38:00.374+0800] {logging_mixin.py:190} INFO - [2025-04-20T21:38:00.373+0800] {dagbag.py:588} INFO - Filling up the DagBag from /mnt/c/Users/wu_li/OneDrive/Desktop/Airflow_pract/dags/first_dag.py
[2025-04-20T21:38:00.411+0800] {logging_mixin.py:190} INFO - [2025-04-20T21:38:00.401+0800] {dagbag.py:387} ERROR - Failed to import: /mnt/c/Users/wu_li/OneDrive/Desktop/Airflow_pract/dags/first_dag.py
Traceback (most recent call last):
  File "/mnt/c/Users/wu_li/OneDrive/Desktop/Airflow_pract/venv/lib/python3.9/site-packages/airflow/models/dagbag.py", line 383, in parse
    loader.exec_module(new_module)
  File "<frozen importlib._bootstrap_external>", line 850, in exec_module
  File "<frozen importlib._bootstrap>", line 228, in _call_with_frames_removed
  File "/mnt/c/Users/wu_li/OneDrive/Desktop/Airflow_pract/dags/first_dag.py", line 2, in <module>
    from airflow import dag
ImportError: cannot import name 'dag' from 'airflow' (/mnt/c/Users/wu_li/OneDrive/Desktop/Airflow_pract/venv/lib/python3.9/site-packages/airflow/__init__.py)
[2025-04-20T21:38:00.414+0800] {processor.py:927} WARNING - No viable dags retrieved from /mnt/c/Users/wu_li/OneDrive/Desktop/Airflow_pract/dags/first_dag.py
[2025-04-20T21:38:00.451+0800] {processor.py:208} INFO - Processing /mnt/c/Users/wu_li/OneDrive/Desktop/Airflow_pract/dags/first_dag.py took 0.092 seconds
[2025-04-20T21:38:54.843+0800] {processor.py:186} INFO - Started process (PID=117624) to work on /mnt/c/Users/wu_li/OneDrive/Desktop/Airflow_pract/dags/first_dag.py
[2025-04-20T21:38:54.845+0800] {processor.py:914} INFO - Processing file /mnt/c/Users/wu_li/OneDrive/Desktop/Airflow_pract/dags/first_dag.py for tasks to queue
[2025-04-20T21:38:54.847+0800] {logging_mixin.py:190} INFO - [2025-04-20T21:38:54.846+0800] {dagbag.py:588} INFO - Filling up the DagBag from /mnt/c/Users/wu_li/OneDrive/Desktop/Airflow_pract/dags/first_dag.py
[2025-04-20T21:38:54.890+0800] {logging_mixin.py:190} INFO - [2025-04-20T21:38:54.877+0800] {dagbag.py:387} ERROR - Failed to import: /mnt/c/Users/wu_li/OneDrive/Desktop/Airflow_pract/dags/first_dag.py
Traceback (most recent call last):
  File "/mnt/c/Users/wu_li/OneDrive/Desktop/Airflow_pract/venv/lib/python3.9/site-packages/airflow/models/dagbag.py", line 383, in parse
    loader.exec_module(new_module)
  File "<frozen importlib._bootstrap_external>", line 850, in exec_module
  File "<frozen importlib._bootstrap>", line 228, in _call_with_frames_removed
  File "/mnt/c/Users/wu_li/OneDrive/Desktop/Airflow_pract/dags/first_dag.py", line 2, in <module>
    from airflow import dag
ImportError: cannot import name 'dag' from 'airflow' (/mnt/c/Users/wu_li/OneDrive/Desktop/Airflow_pract/venv/lib/python3.9/site-packages/airflow/__init__.py)
[2025-04-20T21:38:54.893+0800] {processor.py:927} WARNING - No viable dags retrieved from /mnt/c/Users/wu_li/OneDrive/Desktop/Airflow_pract/dags/first_dag.py
[2025-04-20T21:38:54.933+0800] {processor.py:208} INFO - Processing /mnt/c/Users/wu_li/OneDrive/Desktop/Airflow_pract/dags/first_dag.py took 0.106 seconds
[2025-04-20T21:39:40.834+0800] {processor.py:186} INFO - Started process (PID=118092) to work on /mnt/c/Users/wu_li/OneDrive/Desktop/Airflow_pract/dags/first_dag.py
[2025-04-20T21:39:40.836+0800] {processor.py:914} INFO - Processing file /mnt/c/Users/wu_li/OneDrive/Desktop/Airflow_pract/dags/first_dag.py for tasks to queue
[2025-04-20T21:39:40.840+0800] {logging_mixin.py:190} INFO - [2025-04-20T21:39:40.839+0800] {dagbag.py:588} INFO - Filling up the DagBag from /mnt/c/Users/wu_li/OneDrive/Desktop/Airflow_pract/dags/first_dag.py
[2025-04-20T21:39:40.889+0800] {logging_mixin.py:190} INFO - [2025-04-20T21:39:40.876+0800] {dagbag.py:387} ERROR - Failed to import: /mnt/c/Users/wu_li/OneDrive/Desktop/Airflow_pract/dags/first_dag.py
Traceback (most recent call last):
  File "/mnt/c/Users/wu_li/OneDrive/Desktop/Airflow_pract/venv/lib/python3.9/site-packages/airflow/models/dagbag.py", line 383, in parse
    loader.exec_module(new_module)
  File "<frozen importlib._bootstrap_external>", line 850, in exec_module
  File "<frozen importlib._bootstrap>", line 228, in _call_with_frames_removed
  File "/mnt/c/Users/wu_li/OneDrive/Desktop/Airflow_pract/dags/first_dag.py", line 2, in <module>
    from airflow import dag
ImportError: cannot import name 'dag' from 'airflow' (/mnt/c/Users/wu_li/OneDrive/Desktop/Airflow_pract/venv/lib/python3.9/site-packages/airflow/__init__.py)
[2025-04-20T21:39:40.891+0800] {processor.py:927} WARNING - No viable dags retrieved from /mnt/c/Users/wu_li/OneDrive/Desktop/Airflow_pract/dags/first_dag.py
[2025-04-20T21:39:40.936+0800] {processor.py:208} INFO - Processing /mnt/c/Users/wu_li/OneDrive/Desktop/Airflow_pract/dags/first_dag.py took 0.118 seconds
[2025-04-20T21:40:23.398+0800] {processor.py:186} INFO - Started process (PID=118503) to work on /mnt/c/Users/wu_li/OneDrive/Desktop/Airflow_pract/dags/first_dag.py
[2025-04-20T21:40:23.400+0800] {processor.py:914} INFO - Processing file /mnt/c/Users/wu_li/OneDrive/Desktop/Airflow_pract/dags/first_dag.py for tasks to queue
[2025-04-20T21:40:23.405+0800] {logging_mixin.py:190} INFO - [2025-04-20T21:40:23.404+0800] {dagbag.py:588} INFO - Filling up the DagBag from /mnt/c/Users/wu_li/OneDrive/Desktop/Airflow_pract/dags/first_dag.py
[2025-04-20T21:40:23.448+0800] {logging_mixin.py:190} INFO - [2025-04-20T21:40:23.436+0800] {dagbag.py:387} ERROR - Failed to import: /mnt/c/Users/wu_li/OneDrive/Desktop/Airflow_pract/dags/first_dag.py
Traceback (most recent call last):
  File "/mnt/c/Users/wu_li/OneDrive/Desktop/Airflow_pract/venv/lib/python3.9/site-packages/airflow/models/dagbag.py", line 383, in parse
    loader.exec_module(new_module)
  File "<frozen importlib._bootstrap_external>", line 850, in exec_module
  File "<frozen importlib._bootstrap>", line 228, in _call_with_frames_removed
  File "/mnt/c/Users/wu_li/OneDrive/Desktop/Airflow_pract/dags/first_dag.py", line 2, in <module>
    from airflow import dag
ImportError: cannot import name 'dag' from 'airflow' (/mnt/c/Users/wu_li/OneDrive/Desktop/Airflow_pract/venv/lib/python3.9/site-packages/airflow/__init__.py)
[2025-04-20T21:40:23.451+0800] {processor.py:927} WARNING - No viable dags retrieved from /mnt/c/Users/wu_li/OneDrive/Desktop/Airflow_pract/dags/first_dag.py
[2025-04-20T21:40:23.497+0800] {processor.py:208} INFO - Processing /mnt/c/Users/wu_li/OneDrive/Desktop/Airflow_pract/dags/first_dag.py took 0.114 seconds
[2025-04-20T21:41:06.118+0800] {processor.py:186} INFO - Started process (PID=119144) to work on /mnt/c/Users/wu_li/OneDrive/Desktop/Airflow_pract/dags/first_dag.py
[2025-04-20T21:41:06.121+0800] {processor.py:914} INFO - Processing file /mnt/c/Users/wu_li/OneDrive/Desktop/Airflow_pract/dags/first_dag.py for tasks to queue
[2025-04-20T21:41:06.125+0800] {logging_mixin.py:190} INFO - [2025-04-20T21:41:06.123+0800] {dagbag.py:588} INFO - Filling up the DagBag from /mnt/c/Users/wu_li/OneDrive/Desktop/Airflow_pract/dags/first_dag.py
[2025-04-20T21:41:06.163+0800] {logging_mixin.py:190} INFO - [2025-04-20T21:41:06.152+0800] {dagbag.py:387} ERROR - Failed to import: /mnt/c/Users/wu_li/OneDrive/Desktop/Airflow_pract/dags/first_dag.py
Traceback (most recent call last):
  File "/mnt/c/Users/wu_li/OneDrive/Desktop/Airflow_pract/venv/lib/python3.9/site-packages/airflow/models/dagbag.py", line 383, in parse
    loader.exec_module(new_module)
  File "<frozen importlib._bootstrap_external>", line 850, in exec_module
  File "<frozen importlib._bootstrap>", line 228, in _call_with_frames_removed
  File "/mnt/c/Users/wu_li/OneDrive/Desktop/Airflow_pract/dags/first_dag.py", line 11, in <module>
    with DAG(
TypeError: __init__() got an unexpected keyword argument 'descirption'
[2025-04-20T21:41:06.166+0800] {processor.py:927} WARNING - No viable dags retrieved from /mnt/c/Users/wu_li/OneDrive/Desktop/Airflow_pract/dags/first_dag.py
[2025-04-20T21:41:06.220+0800] {processor.py:208} INFO - Processing /mnt/c/Users/wu_li/OneDrive/Desktop/Airflow_pract/dags/first_dag.py took 0.119 seconds
[2025-04-20T21:41:50.544+0800] {processor.py:186} INFO - Started process (PID=119620) to work on /mnt/c/Users/wu_li/OneDrive/Desktop/Airflow_pract/dags/first_dag.py
[2025-04-20T21:41:50.551+0800] {processor.py:914} INFO - Processing file /mnt/c/Users/wu_li/OneDrive/Desktop/Airflow_pract/dags/first_dag.py for tasks to queue
[2025-04-20T21:41:50.560+0800] {logging_mixin.py:190} INFO - [2025-04-20T21:41:50.555+0800] {dagbag.py:588} INFO - Filling up the DagBag from /mnt/c/Users/wu_li/OneDrive/Desktop/Airflow_pract/dags/first_dag.py
[2025-04-20T21:41:50.625+0800] {logging_mixin.py:190} INFO - [2025-04-20T21:41:50.606+0800] {dagbag.py:387} ERROR - Failed to import: /mnt/c/Users/wu_li/OneDrive/Desktop/Airflow_pract/dags/first_dag.py
Traceback (most recent call last):
  File "/mnt/c/Users/wu_li/OneDrive/Desktop/Airflow_pract/venv/lib/python3.9/site-packages/airflow/models/dagbag.py", line 383, in parse
    loader.exec_module(new_module)
  File "<frozen importlib._bootstrap_external>", line 850, in exec_module
  File "<frozen importlib._bootstrap>", line 228, in _call_with_frames_removed
  File "/mnt/c/Users/wu_li/OneDrive/Desktop/Airflow_pract/dags/first_dag.py", line 11, in <module>
    with DAG(
TypeError: __init__() got an unexpected keyword argument 'descirption'
[2025-04-20T21:41:50.629+0800] {processor.py:927} WARNING - No viable dags retrieved from /mnt/c/Users/wu_li/OneDrive/Desktop/Airflow_pract/dags/first_dag.py
[2025-04-20T21:41:50.698+0800] {processor.py:208} INFO - Processing /mnt/c/Users/wu_li/OneDrive/Desktop/Airflow_pract/dags/first_dag.py took 0.182 seconds
[2025-04-20T21:42:38.332+0800] {processor.py:186} INFO - Started process (PID=119968) to work on /mnt/c/Users/wu_li/OneDrive/Desktop/Airflow_pract/dags/first_dag.py
[2025-04-20T21:42:38.335+0800] {processor.py:914} INFO - Processing file /mnt/c/Users/wu_li/OneDrive/Desktop/Airflow_pract/dags/first_dag.py for tasks to queue
[2025-04-20T21:42:38.339+0800] {logging_mixin.py:190} INFO - [2025-04-20T21:42:38.337+0800] {dagbag.py:588} INFO - Filling up the DagBag from /mnt/c/Users/wu_li/OneDrive/Desktop/Airflow_pract/dags/first_dag.py
[2025-04-20T21:42:38.365+0800] {logging_mixin.py:190} INFO - [2025-04-20T21:42:38.355+0800] {dagbag.py:387} ERROR - Failed to import: /mnt/c/Users/wu_li/OneDrive/Desktop/Airflow_pract/dags/first_dag.py
Traceback (most recent call last):
  File "/mnt/c/Users/wu_li/OneDrive/Desktop/Airflow_pract/venv/lib/python3.9/site-packages/airflow/models/dagbag.py", line 383, in parse
    loader.exec_module(new_module)
  File "<frozen importlib._bootstrap_external>", line 850, in exec_module
  File "<frozen importlib._bootstrap>", line 228, in _call_with_frames_removed
  File "/mnt/c/Users/wu_li/OneDrive/Desktop/Airflow_pract/dags/first_dag.py", line 11, in <module>
    with DAG(
TypeError: __init__() got an unexpected keyword argument 'descirption'
[2025-04-20T21:42:38.368+0800] {processor.py:927} WARNING - No viable dags retrieved from /mnt/c/Users/wu_li/OneDrive/Desktop/Airflow_pract/dags/first_dag.py
[2025-04-20T21:42:38.406+0800] {processor.py:208} INFO - Processing /mnt/c/Users/wu_li/OneDrive/Desktop/Airflow_pract/dags/first_dag.py took 0.087 seconds
[2025-04-20T21:43:29.012+0800] {processor.py:186} INFO - Started process (PID=120417) to work on /mnt/c/Users/wu_li/OneDrive/Desktop/Airflow_pract/dags/first_dag.py
[2025-04-20T21:43:29.014+0800] {processor.py:914} INFO - Processing file /mnt/c/Users/wu_li/OneDrive/Desktop/Airflow_pract/dags/first_dag.py for tasks to queue
[2025-04-20T21:43:29.020+0800] {logging_mixin.py:190} INFO - [2025-04-20T21:43:29.016+0800] {dagbag.py:588} INFO - Filling up the DagBag from /mnt/c/Users/wu_li/OneDrive/Desktop/Airflow_pract/dags/first_dag.py
[2025-04-20T21:43:29.050+0800] {logging_mixin.py:190} INFO - [2025-04-20T21:43:29.040+0800] {dagbag.py:387} ERROR - Failed to import: /mnt/c/Users/wu_li/OneDrive/Desktop/Airflow_pract/dags/first_dag.py
Traceback (most recent call last):
  File "/mnt/c/Users/wu_li/OneDrive/Desktop/Airflow_pract/venv/lib/python3.9/site-packages/airflow/models/dagbag.py", line 383, in parse
    loader.exec_module(new_module)
  File "<frozen importlib._bootstrap_external>", line 850, in exec_module
  File "<frozen importlib._bootstrap>", line 228, in _call_with_frames_removed
  File "/mnt/c/Users/wu_li/OneDrive/Desktop/Airflow_pract/dags/first_dag.py", line 11, in <module>
    with DAG(
TypeError: __init__() got an unexpected keyword argument 'descirption'
[2025-04-20T21:43:29.057+0800] {processor.py:927} WARNING - No viable dags retrieved from /mnt/c/Users/wu_li/OneDrive/Desktop/Airflow_pract/dags/first_dag.py
[2025-04-20T21:43:29.111+0800] {processor.py:208} INFO - Processing /mnt/c/Users/wu_li/OneDrive/Desktop/Airflow_pract/dags/first_dag.py took 0.115 seconds
[2025-04-20T21:44:17.648+0800] {processor.py:186} INFO - Started process (PID=120872) to work on /mnt/c/Users/wu_li/OneDrive/Desktop/Airflow_pract/dags/first_dag.py
[2025-04-20T21:44:17.650+0800] {processor.py:914} INFO - Processing file /mnt/c/Users/wu_li/OneDrive/Desktop/Airflow_pract/dags/first_dag.py for tasks to queue
[2025-04-20T21:44:17.652+0800] {logging_mixin.py:190} INFO - [2025-04-20T21:44:17.651+0800] {dagbag.py:588} INFO - Filling up the DagBag from /mnt/c/Users/wu_li/OneDrive/Desktop/Airflow_pract/dags/first_dag.py
[2025-04-20T21:44:17.689+0800] {logging_mixin.py:190} INFO - [2025-04-20T21:44:17.679+0800] {dagbag.py:387} ERROR - Failed to import: /mnt/c/Users/wu_li/OneDrive/Desktop/Airflow_pract/dags/first_dag.py
Traceback (most recent call last):
  File "/mnt/c/Users/wu_li/OneDrive/Desktop/Airflow_pract/venv/lib/python3.9/site-packages/airflow/models/dagbag.py", line 383, in parse
    loader.exec_module(new_module)
  File "<frozen importlib._bootstrap_external>", line 850, in exec_module
  File "<frozen importlib._bootstrap>", line 228, in _call_with_frames_removed
  File "/mnt/c/Users/wu_li/OneDrive/Desktop/Airflow_pract/dags/first_dag.py", line 11, in <module>
    with DAG(
TypeError: __init__() got an unexpected keyword argument 'descirption'
[2025-04-20T21:44:17.691+0800] {processor.py:927} WARNING - No viable dags retrieved from /mnt/c/Users/wu_li/OneDrive/Desktop/Airflow_pract/dags/first_dag.py
[2025-04-20T21:44:17.741+0800] {processor.py:208} INFO - Processing /mnt/c/Users/wu_li/OneDrive/Desktop/Airflow_pract/dags/first_dag.py took 0.105 seconds
[2025-04-20T21:45:01.909+0800] {processor.py:186} INFO - Started process (PID=121383) to work on /mnt/c/Users/wu_li/OneDrive/Desktop/Airflow_pract/dags/first_dag.py
[2025-04-20T21:45:01.911+0800] {processor.py:914} INFO - Processing file /mnt/c/Users/wu_li/OneDrive/Desktop/Airflow_pract/dags/first_dag.py for tasks to queue
[2025-04-20T21:45:01.915+0800] {logging_mixin.py:190} INFO - [2025-04-20T21:45:01.913+0800] {dagbag.py:588} INFO - Filling up the DagBag from /mnt/c/Users/wu_li/OneDrive/Desktop/Airflow_pract/dags/first_dag.py
[2025-04-20T21:45:01.999+0800] {logging_mixin.py:190} INFO - [2025-04-20T21:45:01.935+0800] {dagbag.py:387} ERROR - Failed to import: /mnt/c/Users/wu_li/OneDrive/Desktop/Airflow_pract/dags/first_dag.py
Traceback (most recent call last):
  File "/mnt/c/Users/wu_li/OneDrive/Desktop/Airflow_pract/venv/lib/python3.9/site-packages/airflow/models/dagbag.py", line 383, in parse
    loader.exec_module(new_module)
  File "<frozen importlib._bootstrap_external>", line 850, in exec_module
  File "<frozen importlib._bootstrap>", line 228, in _call_with_frames_removed
  File "/mnt/c/Users/wu_li/OneDrive/Desktop/Airflow_pract/dags/first_dag.py", line 11, in <module>
    with DAG(
TypeError: __init__() got an unexpected keyword argument 'descirption'
[2025-04-20T21:45:02.004+0800] {processor.py:927} WARNING - No viable dags retrieved from /mnt/c/Users/wu_li/OneDrive/Desktop/Airflow_pract/dags/first_dag.py
[2025-04-20T21:45:02.088+0800] {processor.py:208} INFO - Processing /mnt/c/Users/wu_li/OneDrive/Desktop/Airflow_pract/dags/first_dag.py took 0.196 seconds
